Workbook

Sheet Dashboard
A1: Elektronický zápisník letů
A3: Metrika | B3: Hodnota | D3: Funkce | E3: Hodin
A4: Celkový nálet | B4: =SUM('Zápisník letů'!$L$2:$L$1018) -> 11.260417 | D4: PIC | E4: =B5*24 -> 212.5
A5: PIC celkem | B5: =SUMIFS('Zápisník letů'!$L$2:$L$1018,'Zápisník letů'!$Q$2:$Q$1018,"PIC") -> 8.8541667 | D5: DUAL | E5: =B8*24 -> 32.1
A6: PIC ULL | B6: =SUMIFS('Zápisník letů'!$L$2:$L$1018,'Zápisník letů'!$Q$2:$Q$1018,"PIC",'Zápisník letů'!$B$2:$B$1018,"ULL") -> 8.5083333 | D6: Safety Pilot | E6: =B9*24 -> 25.65
A7: PIC EASA | B7: =SUMIFS('Zápisník letů'!$L$2:$L$1018,'Zápisník letů'!$Q$2:$Q$1018,"PIC",'Zápisník letů'!$B$2:$B$1018,"EASA") -> 0.34583333 | D7: Ostatní | E7: =SUMIFS('Zápisník letů'!$L$2:$L$1018,'Zápisník letů'!$Q$2:$Q$1018,"CO-PILOT")*24+SUMIFS('Zápisník letů'!$L$2:$L$1018,'Zápisník letů'!$Q$2:$Q$1018,"PAX")*24+SUMIFS('Zápisník letů'!$L$2:$L$1018,'Zápisník letů'!$Q$2:$Q$1018,"OBSERVER")*24 -> 0
A8: DUAL | B8: =SUMIFS('Zápisník letů'!$L$2:$L$1018,'Zápisník letů'!$Q$2:$Q$1018,"DUAL") -> 1.3375
A9: Safety Pilot | B9: =SUMIFS('Zápisník letů'!$L$2:$L$1018,'Zápisník letů'!$Q$2:$Q$1018,"SAFETY PILOT") -> 1.06875
A10: ULL celkem | B10: =SUMIFS('Zápisník letů'!$L$2:$L$1018,'Zápisník letů'!$B$2:$B$1018,"ULL") -> 9.3270833 | D10: Evidence | E10: Hodin
A11: EASA celkem | B11: =SUMIFS('Zápisník letů'!$L$2:$L$1018,'Zápisník letů'!$B$2:$B$1018,"EASA") -> 1.9333333 | D11: ULL | E11: =B10*24 -> 223.85
A12: Air Time | B12: =SUM('Zápisník letů'!$M$2:$M$1018) -> 9.8631944 | D12: EASA | E12: =B11*24 -> 46.4
A13: Počet letů | B13: =COUNTA('Zápisník letů'!$A$2:$A$1018) -> 195
A14: Počet startů | B14: =SUM('Zápisník letů'!$N$2:$N$1018) -> 570
A15: Náklady celkem | B15: =SUM('Zápisník letů'!$T$2:$T$1018) -> 678894.5 | D15: PIC evidence | E15: Hodin
A16: Kontrola | B16: =COUNTIFS('Zápisník letů'!$A$2:$A$1018,"<>",'Zápisník letů'!$V$2:$V$1018,"<>OK") -> 0 | D16: PIC ULL | E16: =B6*24 -> 204.2
D17: PIC EASA | E17: =B7*24 -> 8.3
D20: Rok | E20: Hodin
D21: 2020 | E21: =Souhrny!C4*24 -> 23.9
D22: 2021 | E22: =Souhrny!C5*24 -> 43.383333
D23: 2022 | E23: =Souhrny!C6*24 -> 47.633333
D24: 2023 | E24: =Souhrny!C7*24 -> 39.033333
D25: 2024 | E25: =Souhrny!C8*24 -> 48.183333
D26: 2025 | E26: =Souhrny!C9*24 -> 46.733333
D27: 2026 | E27: =Souhrny!C10*24 -> 21.383333
D28: 2027 | E28: =Souhrny!C11*24 -> 0
D29: 2028 | E29: =Souhrny!C12*24 -> 0
D30: 2029 | E30: =Souhrny!C13*24 -> 0
D31: 2030 | E31: =Souhrny!C14*24 -> 0

Sheet Zápisník letů
A1: Datum | B1: Evidence | C1: Imatrikulace | D1: Typ | E1: Třída | F1: Odlet | G1: Přílet | H1: Off Block | I1: Takeoff | J1: Landing | K1: On Block | L1: Block Time | M1: Air Time | N1: Starty | O1: Velitel letadla | P1: Instruktor | Q1: Funkce | R1: Úloha | S1: Cena Kč/h | T1: Cena letu Kč | U1: Poznámka | V1: Kontrola
A2: 43930 | B2: ULL | C2: OK-XAI04 | D2: Bristell | E2: ULL | F2: LKSZ | G2: LKSZ | H2: 0.36388889 | I2: 0.36736111 | J2: 0.42986111 | K2: 0.43333333 | L2: =IF($A2="","",IF(AND(ISNUMBER($H2),ISNUMBER($K2)),MOD($K2-$H2,1),"")) -> 0.069444444 | M2: =IF($A2="","",IF(AND(ISNUMBER($I2),ISNUMBER($J2)),MOD($J2-$I2,1),"")) -> 0.0625 | N2: 2 | O2: Točík Filip | Q2: PIC | S2: 1860 | T2: =IF($A2="","",IF(OR($S2="", $S2<=0, $L2=""),"",ROUND($L2*24*$S2,2))) -> 3100 | V2: =IF($A2="","",IF(OR(YEAR($A2)<2020,YEAR($A2)>2030),"Podezřelé datum",IF(OR($F2="",$G2=""),"Chybí letiště",IF(OR($H2="",$I2="",$J2="",$K2=""),"Chybí čas",IF(OR($H2>$I2,$I2>$J2,$J2>$K2),"Časy mimo pořadí",IF($M2>$L2,"Air > Block",IF(OR($S2="", $S2<=0),"Chybí sazba","OK"))))))) -> OK
A3: 43944 | B3: ULL | C3: OK-XAI04 | D3: Bristell | E3: ULL | F3: LKSZ | G3: LKKEJZ | H3: 0.45138889 | I3: 0.45486111 | J3: 0.49236111 | K3: 0.49583333 | L3: =IF($A3="","",IF(AND(ISNUMBER($H3),ISNUMBER($K3)),MOD($K3-$H3,1),"")) -> 0.044444444 | M3: =IF($A3="","",IF(AND(ISNUMBER($I3),ISNUMBER($J3)),MOD($J3-$I3,1),"")) -> 0.0375 | N3: 1 | O3: Točík Filip | Q3: PIC | R3: LKSZ-LKKEJZ | S3: 1860 | T3: =IF($A3="","",IF(OR($S3="", $S3<=0, $L3=""),"",ROUND($L3*24*$S3,2))) -> 1984 | V3: =IF($A3="","",IF(OR(YEAR($A3)<2020,YEAR($A3)>2030),"Podezřelé datum",IF(OR($F3="",$G3=""),"Chybí letiště",IF(OR($H3="",$I3="",$J3="",$K3=""),"Chybí čas",IF(OR($H3>$I3,$I3>$J3,$J3>$K3),"Časy mimo pořadí",IF($M3>$L3,"Air > Block",IF(OR($S3="", $S3<=0),"Chybí sazba","OK"))))))) -> OK
A4: 43944 | B4: ULL | C4: OK-XAI04 | D4: Bristell | E4: ULL | F4: LKKEJZ | G4: LKSZ | H4: 0.54861111 | I4: 0.55208333 | J4: 0.58541667 | K4: 0.58888889 | L4: =IF($A4="","",IF(AND(ISNUMBER($H4),ISNUMBER($K4)),MOD($K4-$H4,1),"")) -> 0.040277778 | M4: =IF($A4="","",IF(AND(ISNUMBER($I4),ISNUMBER($J4)),MOD($J4-$I4,1),"")) -> 0.033333333 | N4: 1 | O4: Točík Filip | Q4: PIC | R4: LKKEJZ-LKSZ | S4: 1860 | T4: =IF($A4="","",IF(OR($S4="", $S4<=0, $L4=""),"",ROUND($L4*24*$S4,2))) -> 1798 | V4: =IF($A4="","",IF(OR(YEAR($A4)<2020,YEAR($A4)>2030),"Podezřelé datum",IF(OR($F4="",$G4=""),"Chybí letiště",IF(OR($H4="",$I4="",$J4="",$K4=""),"Chybí čas",IF(OR($H4>$I4,$I4>$J4,$J4>$K4),"Časy mimo pořadí",IF($M4>$L4,"Air > Block",IF(OR($S4="", $S4<=0),"Chybí sazba","OK"))))))) -> OK
A5: 43973 | B5: ULL | C5: OK-XAI04 | D5: Bristell | E5: ULL | F5: LKSZ | G5: LKSZ | H5: 0.39097222 | I5: 0.39444444 | J5: 0.46944444 | K5: 0.47291667 | L5: =IF($A5="","",IF(AND(ISNUMBER($H5),ISNUMBER($K5)),MOD($K5-$H5,1),"")) -> 0.081944444 | M5: =IF($A5="","",IF(AND(ISNUMBER($I5),ISNUMBER($J5)),MOD($J5-$I5,1),"")) -> 0.075 | N5: 2 | O5: Točík Filip | Q5: PIC | S5: 1860 | T5: =IF($A5="","",IF(OR($S5="", $S5<=0, $L5=""),"",ROUND($L5*24*$S5,2))) -> 3658 | V5: =IF($A5="","",IF(OR(YEAR($A5)<2020,YEAR($A5)>2030),"Podezřelé datum",IF(OR($F5="",$G5=""),"Chybí letiště",IF(OR($H5="",$I5="",$J5="",$K5=""),"Chybí čas",IF(OR($H5>$I5,$I5>$J5,$J5>$K5),"Časy mimo pořadí",IF($M5>$L5,"Air > Block",IF(OR($S5="", $S5<=0),"Chybí sazba","OK"))))))) -> OK
A6: 44078 | B6: ULL | C6: OK-XAI04 | D6: Bristell | E6: ULL | F6: LKSZ | G6: LKSZ | H6: 0.58680556 | I6: 0.59027778 | J6: 0.60694444 | K6: 0.61041667 | L6: =IF($A6="","",IF(AND(ISNUMBER($H6),ISNUMBER($K6)),MOD($K6-$H6,1),"")) -> 0.023611111 | M6: =IF($A6="","",IF(AND(ISNUMBER($I6),ISNUMBER($J6)),MOD($J6-$I6,1),"")) -> 0.016666667 | N6: 1 | O6: Točík Filip | P6: Šindelář Petr | Q6: DUAL | S6: 1860 | T6: =IF($A6="","",IF(OR($S6="", $S6<=0, $L6=""),"",ROUND($L6*24*$S6,2))) -> 1054 | V6: =IF($A6="","",IF(OR(YEAR($A6)<2020,YEAR($A6)>2030),"Podezřelé datum",IF(OR($F6="",$G6=""),"Chybí letiště",IF(OR($H6="",$I6="",$J6="",$K6=""),"Chybí čas",IF(OR($H6>$I6,$I6>$J6,$J6>$K6),"Časy mimo pořadí",IF($M6>$L6,"Air > Block",IF(OR($S6="", $S6<=0),"Chybí sazba","OK"))))))) -> OK
A7: 44080 | B7: ULL | C7: OK-XAI04 | D7: Bristell | E7: ULL | F7: LKSZ | G7: LKSZ | H7: 0.47569444 | I7: 0.47916667 | J7: 0.5125 | K7: 0.51597222 | L7: =IF($A7="","",IF(AND(ISNUMBER($H7),ISNUMBER($K7)),MOD($K7-$H7,1),"")) -> 0.040277778 | M7: =IF($A7="","",IF(AND(ISNUMBER($I7),ISNUMBER($J7)),MOD($J7-$I7,1),"")) -> 0.033333333 | N7: 9 | O7: Točík Filip | P7: Šindelář Petr | Q7: DUAL | S7: 1860 | T7: =IF($A7="","",IF(OR($S7="", $S7<=0, $L7=""),"",ROUND($L7*24*$S7,2))) -> 1798 | V7: =IF($A7="","",IF(OR(YEAR($A7)<2020,YEAR($A7)>2030),"Podezřelé datum",IF(OR($F7="",$G7=""),"Chybí letiště",IF(OR($H7="",$I7="",$J7="",$K7=""),"Chybí čas",IF(OR($H7>$I7,$I7>$J7,$J7>$K7),"Časy mimo pořadí",IF($M7>$L7,"Air > Block",IF(OR($S7="", $S7<=0),"Chybí sazba","OK"))))))) -> OK
A8: 44081 | B8: ULL | C8: OK-XAI04 | D8: Bristell | E8: ULL | F8: LKSZ | G8: LKSZ | H8: 0.61319444 | I8: 0.61666667 | J8: 0.64166667 | K8: 0.64513889 | L8: =IF($A8="","",IF(AND(ISNUMBER($H8),ISNUMBER($K8)),MOD($K8-$H8,1),"")) -> 0.031944444 | M8: =IF($A8="","",IF(AND(ISNUMBER($I8),ISNUMBER($J8)),MOD($J8-$I8,1),"")) -> 0.025 | N8: 6 | O8: Točík Filip | P8: Šimon Jan | Q8: DUAL | S8: 1860 | T8: =IF($A8="","",IF(OR($S8="", $S8<=0, $L8=""),"",ROUND($L8*24*$S8,2))) -> 1426 | V8: =IF($A8="","",IF(OR(YEAR($A8)<2020,YEAR($A8)>2030),"Podezřelé datum",IF(OR($F8="",$G8=""),"Chybí letiště",IF(OR($H8="",$I8="",$J8="",$K8=""),"Chybí čas",IF(OR($H8>$I8,$I8>$J8,$J8>$K8),"Časy mimo pořadí",IF($M8>$L8,"Air > Block",IF(OR($S8="", $S8<=0),"Chybí sazba","OK"))))))) -> OK
A9: 44082 | B9: ULL | C9: OK-XAI04 | D9: Bristell | E9: ULL | F9: LKSZ | G9: LKSZ | H9: 0.68541667 | I9: 0.68888889 | J9: 0.72222222 | K9: 0.72569444 | L9: =IF($A9="","",IF(AND(ISNUMBER($H9),ISNUMBER($K9)),MOD($K9-$H9,1),"")) -> 0.040277778 | M9: =IF($A9="","",IF(AND(ISNUMBER($I9),ISNUMBER($J9)),MOD($J9-$I9,1),"")) -> 0.033333333 | N9: 5 | O9: Točík Filip | P9: Šimon Jan | Q9: DUAL | S9: 1860 | T9: =IF($A9="","",IF(OR($S9="", $S9<=0, $L9=""),"",ROUND($L9*24*$S9,2))) -> 1798 | V9: =IF($A9="","",IF(OR(YEAR($A9)<2020,YEAR($A9)>2030),"Podezřelé datum",IF(OR($F9="",$G9=""),"Chybí letiště",IF(OR($H9="",$I9="",$J9="",$K9=""),"Chybí čas",IF(OR($H9>$I9,$I9>$J9,$J9>$K9),"Časy mimo pořadí",IF($M9>$L9,"Air > Block",IF(OR($S9="", $S9<=0),"Chybí sazba","OK"))))))) -> OK
A10: 44086 | B10: ULL | C10: OK-XAI04 | D10: Bristell | E10: ULL | F10: LKSZ | G10: LKSZ | H10: 0.34027778 | I10: 0.34375 | J10: 0.36875 | K10: 0.37222222 | L10: =IF($A10="","",IF(AND(ISNUMBER($H10),ISNUMBER($K10)),MOD($K10-$H10,1),"")) -> 0.031944444 | M10: =IF($A10="","",IF(AND(ISNUMBER($I10),ISNUMBER($J10)),MOD($J10-$I10,1),"")) -> 0.025 | N10: 8 | O10: Točík Filip | Q10: PIC | S10: 1860 | T10: =IF($A10="","",IF(OR($S10="", $S10<=0, $L10=""),"",ROUND($L10*24*$S10,2))) -> 1426 | V10: =IF($A10="","",IF(OR(YEAR($A10)<2020,YEAR($A10)>2030),"Podezřelé datum",IF(OR($F10="",$G10=""),"Chybí letiště",IF(OR($H10="",$I10="",$J10="",$K10=""),"Chybí čas",IF(OR($H10>$I10,$I10>$J10,$J10>$K10),"Časy mimo pořadí",IF($M10>$L10,"Air > Block",IF(OR($S10="", $S10<=0),"Chybí sazba","OK"))))))) -> OK
A11: 44086 | B11: ULL | C11: OK-XAI04 | D11: Bristell | E11: ULL | F11: LKSZ | G11: LKSZ | H11: 0.39166667 | I11: 0.39513889 | J11: 0.40763889 | K11: 0.41111111 | L11: =IF($A11="","",IF(AND(ISNUMBER($H11),ISNUMBER($K11)),MOD($K11-$H11,1),"")) -> 0.019444444 | M11: =IF($A11="","",IF(AND(ISNUMBER($I11),ISNUMBER($J11)),MOD($J11-$I11,1),"")) -> 0.0125 | N11: 5 | O11: Točík Filip | Q11: PIC | S11: 1860 | T11: =IF($A11="","",IF(OR($S11="", $S11<=0, $L11=""),"",ROUND($L11*24*$S11,2))) -> 868 | V11: =IF($A11="","",IF(OR(YEAR($A11)<2020,YEAR($A11)>2030),"Podezřelé datum",IF(OR($F11="",$G11=""),"Chybí letiště",IF(OR($H11="",$I11="",$J11="",$K11=""),"Chybí čas",IF(OR($H11>$I11,$I11>$J11,$J11>$K11),"Časy mimo pořadí",IF($M11>$L11,"Air > Block",IF(OR($S11="", $S11<=0),"Chybí sazba","OK"))))))) -> OK
A12: 44086 | B12: ULL | C12: OK-XAI04 | D12: Bristell | E12: ULL | F12: LKSZ | G12: LKSZ | H12: 0.41111111 | I12: 0.41458333 | J12: 0.42708333 | K12: 0.43055556 | L12: =IF($A12="","",IF(AND(ISNUMBER($H12),ISNUMBER($K12)),MOD($K12-$H12,1),"")) -> 0.019444444 | M12: =IF($A12="","",IF(AND(ISNUMBER($I12),ISNUMBER($J12)),MOD($J12-$I12,1),"")) -> 0.0125 | N12: 5 | O12: Točík Filip | Q12: PIC | S12: 1860 | T12: =IF($A12="","",IF(OR($S12="", $S12<=0, $L12=""),"",ROUND($L12*24*$S12,2))) -> 868 | V12: =IF($A12="","",IF(OR(YEAR($A12)<2020,YEAR($A12)>2030),"Podezřelé datum",IF(OR($F12="",$G12=""),"Chybí letiště",IF(OR($H12="",$I12="",$J12="",$K12=""),"Chybí čas",IF(OR($H12>$I12,$I12>$J12,$J12>$K12),"Časy mimo pořadí",IF($M12>$L12,"Air > Block",IF(OR($S12="", $S12<=0),"Chybí sazba","OK"))))))) -> OK
A13: 44087 | B13: ULL | C13: OK-XAI04 | D13: Bristell | E13: ULL | F13: LKSZ | G13: LKSZ | H13: 0.49930556 | I13: 0.50277778 | J13: 0.51944444 | K13: 0.52291667 | L13: =IF($A13="","",IF(AND(ISNUMBER($H13),ISNUMBER($K13)),MOD($K13-$H13,1),"")) -> 0.023611111 | M13: =IF($A13="","",IF(AND(ISNUMBER($I13),ISNUMBER($J13)),MOD($J13-$I13,1),"")) -> 0.016666667 | N13: 6 | O13: Točík Filip | Q13: PIC | S13: 1860 | T13: =IF($A13="","",IF(OR($S13="", $S13<=0, $L13=""),"",ROUND($L13*24*$S13,2))) -> 1054 | V13: =IF($A13="","",IF(OR(YEAR($A13)<2020,YEAR($A13)>2030),"Podezřelé datum",IF(OR($F13="",$G13=""),"Chybí letiště",IF(OR($H13="",$I13="",$J13="",$K13=""),"Chybí čas",IF(OR($H13>$I13,$I13>$J13,$J13>$K13),"Časy mimo pořadí",IF($M13>$L13,"Air > Block",IF(OR($S13="", $S13<=0),"Chybí sazba","OK"))))))) -> OK
A14: 44089 | B14: ULL | C14: OK-XAI04 | D14: Bristell | E14: ULL | F14: LKSZ | G14: LKSZ | H14: 0.58472222 | I14: 0.58819444 | J14: 0.60486111 | K14: 0.60833333 | L14: =IF($A14="","",IF(AND(ISNUMBER($H14),ISNUMBER($K14)),MOD($K14-$H14,1),"")) -> 0.023611111 | M14: =IF($A14="","",IF(AND(ISNUMBER($I14),ISNUMBER($J14)),MOD($J14-$I14,1),"")) -> 0.016666667 | N14: 5 | O14: Točík Filip | Q14: PIC | S14: 1860 | T14: =IF($A14="","",IF(OR($S14="", $S14<=0, $L14=""),"",ROUND($L14*24*$S14,2))) -> 1054 | V14: =IF($A14="","",IF(OR(YEAR($A14)<2020,YEAR($A14)>2030),"Podezřelé datum",IF(OR($F14="",$G14=""),"Chybí letiště",IF(OR($H14="",$I14="",$J14="",$K14=""),"Chybí čas",IF(OR($H14>$I14,$I14>$J14,$J14>$K14),"Časy mimo pořadí",IF($M14>$L14,"Air > Block",IF(OR($S14="", $S14<=0),"Chybí sazba","OK"))))))) -> OK
A15: 44089 | B15: ULL | C15: OK-XAI04 | D15: Bristell | E15: ULL | F15: LKSZ | G15: LKSZ | H15: 0.65138889 | I15: 0.65486111 | J15: 0.67152778 | K15: 0.675 | L15: =IF($A15="","",IF(AND(ISNUMBER($H15),ISNUMBER($K15)),MOD($K15-$H15,1),"")) -> 0.023611111 | M15: =IF($A15="","",IF(AND(ISNUMBER($I15),ISNUMBER($J15)),MOD($J15-$I15,1),"")) -> 0.016666667 | N15: 5 | O15: Točík Filip | Q15: PIC | S15: 1860 | T15: =IF($A15="","",IF(OR($S15="", $S15<=0, $L15=""),"",ROUND($L15*24*$S15,2))) -> 1054 | V15: =IF($A15="","",IF(OR(YEAR($A15)<2020,YEAR($A15)>2030),"Podezřelé datum",IF(OR($F15="",$G15=""),"Chybí letiště",IF(OR($H15="",$I15="",$J15="",$K15=""),"Chybí čas",IF(OR($H15>$I15,$I15>$J15,$J15>$K15),"Časy mimo pořadí",IF($M15>$L15,"Air > Block",IF(OR($S15="", $S15<=0),"Chybí sazba","OK"))))))) -> OK
A16: 44093 | B16: ULL | C16: OK-XAI04 | D16: Bristell | E16: ULL | F16: LKSZ | G16: LKSZ | H16: 0.55902778 | I16: 0.5625 | J16: 0.5875 | K16: 0.59097222 | L16: =IF($A16="","",IF(AND(ISNUMBER($H16),ISNUMBER($K16)),MOD($K16-$H16,1),"")) -> 0.031944444 | M16: =IF($A16="","",IF(AND(ISNUMBER($I16),ISNUMBER($J16)),MOD($J16-$I16,1),"")) -> 0.025 | N16: 4 | O16: Točík Filip | Q16: PIC | S16: 1860 | T16: =IF($A16="","",IF(OR($S16="", $S16<=0, $L16=""),"",ROUND($L16*24*$S16,2))) -> 1426 | V16: =IF($A16="","",IF(OR(YEAR($A16)<2020,YEAR($A16)>2030),"Podezřelé datum",IF(OR($F16="",$G16=""),"Chybí letiště",IF(OR($H16="",$I16="",$J16="",$K16=""),"Chybí čas",IF(OR($H16>$I16,$I16>$J16,$J16>$K16),"Časy mimo pořadí",IF($M16>$L16,"Air > Block",IF(OR($S16="", $S16<=0),"Chybí sazba","OK"))))))) -> OK
A17: 44122 | B17: ULL | C17: OK-XAI04 | D17: Bristell | E17: ULL | F17: LKSZ | G17: LKMH | H17: 0.46875 | I17: 0.47222222 | J17: 0.48472222 | K17: 0.48819444 | L17: =IF($A17="","",IF(AND(ISNUMBER($H17),ISNUMBER($K17)),MOD($K17-$H17,1),"")) -> 0.019444444 | M17: =IF($A17="","",IF(AND(ISNUMBER($I17),ISNUMBER($J17)),MOD($J17-$I17,1),"")) -> 0.0125 | N17: 1 | O17: Točík Filip | Q17: PIC | R17: LKSZ-LKMH | S17: 1860 | T17: =IF($A17="","",IF(OR($S17="", $S17<=0, $L17=""),"",ROUND($L17*24*$S17,2))) -> 868 | V17: =IF($A17="","",IF(OR(YEAR($A17)<2020,YEAR($A17)>2030),"Podezřelé datum",IF(OR($F17="",$G17=""),"Chybí letiště",IF(OR($H17="",$I17="",$J17="",$K17=""),"Chybí čas",IF(OR($H17>$I17,$I17>$J17,$J17>$K17),"Časy mimo pořadí",IF($M17>$L17,"Air > Block",IF(OR($S17="", $S17<=0),"Chybí sazba","OK"))))))) -> OK
A18: 44122 | B18: ULL | C18: OK-XAI04 | D18: Bristell | E18: ULL | F18: LKMH | G18: LKSZ | H18: 0.55972222 | I18: 0.56319444 | J18: 0.58402778 | K18: 0.5875 | L18: =IF($A18="","",IF(AND(ISNUMBER($H18),ISNUMBER($K18)),MOD($K18-$H18,1),"")) -> 0.027777778 | M18: =IF($A18="","",IF(AND(ISNUMBER($I18),ISNUMBER($J18)),MOD($J18-$I18,1),"")) -> 0.020833333 | N18: 1 | O18: Točík Filip | Q18: PIC | R18: LKMH-LKSZ | S18: 1860 | T18: =IF($A18="","",IF(OR($S18="", $S18<=0, $L18=""),"",ROUND($L18*24*$S18,2))) -> 1240 | V18: =IF($A18="","",IF(OR(YEAR($A18)<2020,YEAR($A18)>2030),"Podezřelé datum",IF(OR($F18="",$G18=""),"Chybí letiště",IF(OR($H18="",$I18="",$J18="",$K18=""),"Chybí čas",IF(OR($H18>$I18,$I18>$J18,$J18>$K18),"Časy mimo pořadí",IF($M18>$L18,"Air > Block",IF(OR($S18="", $S18<=0),"Chybí sazba","OK"))))))) -> OK
A19: 44122 | B19: ULL | C19: OK-XAI04 | D19: Bristell | E19: ULL | F19: LKSZ | G19: LKSZ | H19: 0.60277778 | I19: 0.60625 | J19: 0.61875 | K19: 0.62222222 | L19: =IF($A19="","",IF(AND(ISNUMBER($H19),ISNUMBER($K19)),MOD($K19-$H19,1),"")) -> 0.019444444 | M19: =IF($A19="","",IF(AND(ISNUMBER($I19),ISNUMBER($J19)),MOD($J19-$I19,1),"")) -> 0.0125 | N19: 4 | O19: Točík Filip | Q19: PIC | S19: 1860 | T19: =IF($A19="","",IF(OR($S19="", $S19<=0, $L19=""),"",ROUND($L19*24*$S19,2))) -> 868 | V19: =IF($A19="","",IF(OR(YEAR($A19)<2020,YEAR($A19)>2030),"Podezřelé datum",IF(OR($F19="",$G19=""),"Chybí letiště",IF(OR($H19="",$I19="",$J19="",$K19=""),"Chybí čas",IF(OR($H19>$I19,$I19>$J19,$J19>$K19),"Časy mimo pořadí",IF($M19>$L19,"Air > Block",IF(OR($S19="", $S19<=0),"Chybí sazba","OK"))))))) -> OK
A20: 44124 | B20: ULL | C20: OK-XAI04 | D20: Bristell | E20: ULL | F20: LKSZ | G20: LKSZ | H20: 0.55208333 | I20: 0.55555556 | J20: 0.60138889 | K20: 0.60486111 | L20: =IF($A20="","",IF(AND(ISNUMBER($H20),ISNUMBER($K20)),MOD($K20-$H20,1),"")) -> 0.052777778 | M20: =IF($A20="","",IF(AND(ISNUMBER($I20),ISNUMBER($J20)),MOD($J20-$I20,1),"")) -> 0.045833333 | N20: 2 | O20: Točík Filip | P20: Šimon Jan | Q20: DUAL | S20: 1860 | T20: =IF($A20="","",IF(OR($S20="", $S20<=0, $L20=""),"",ROUND($L20*24*$S20,2))) -> 2356 | V20: =IF($A20="","",IF(OR(YEAR($A20)<2020,YEAR($A20)>2030),"Podezřelé datum",IF(OR($F20="",$G20=""),"Chybí letiště",IF(OR($H20="",$I20="",$J20="",$K20=""),"Chybí čas",IF(OR($H20>$I20,$I20>$J20,$J20>$K20),"Časy mimo pořadí",IF($M20>$L20,"Air > Block",IF(OR($S20="", $S20<=0),"Chybí sazba","OK"))))))) -> OK
A21: 44128 | B21: ULL | C21: OK-XAI04 | D21: Bristell | E21: ULL | F21: LKSZ | G21: LKSZ | H21: 0.49513889 | I21: 0.49861111 | J21: 0.54861111 | K21: 0.55208333 | L21: =IF($A21="","",IF(AND(ISNUMBER($H21),ISNUMBER($K21)),MOD($K21-$H21,1),"")) -> 0.056944444 | M21: =IF($A21="","",IF(AND(ISNUMBER($I21),ISNUMBER($J21)),MOD($J21-$I21,1),"")) -> 0.05 | N21: 2 | O21: Točík Filip | Q21: PIC | S21: 1860 | T21: =IF($A21="","",IF(OR($S21="", $S21<=0, $L21=""),"",ROUND($L21*24*$S21,2))) -> 2542 | V21: =IF($A21="","",IF(OR(YEAR($A21)<2020,YEAR($A21)>2030),"Podezřelé datum",IF(OR($F21="",$G21=""),"Chybí letiště",IF(OR($H21="",$I21="",$J21="",$K21=""),"Chybí čas",IF(OR($H21>$I21,$I21>$J21,$J21>$K21),"Časy mimo pořadí",IF($M21>$L21,"Air > Block",IF(OR($S21="", $S21<=0),"Chybí sazba","OK"))))))) -> OK
A22: 44141 | B22: ULL | C22: OK-XAI04 | D22: Bristell | E22: ULL | F22: LKSZ | G22: LKSZ | H22: 0.61111111 | I22: 0.61458333 | J22: 0.64375 | K22: 0.64722222 | L22: =IF($A22="","",IF(AND(ISNUMBER($H22),ISNUMBER($K22)),MOD($K22-$H22,1),"")) -> 0.036111111 | M22: =IF($A22="","",IF(AND(ISNUMBER($I22),ISNUMBER($J22)),MOD($J22-$I22,1),"")) -> 0.029166667 | N22: 2 | O22: Točík Filip | Q22: PIC | S22: 1860 | T22: =IF($A22="","",IF(OR($S22="", $S22<=0, $L22=""),"",ROUND($L22*24*$S22,2))) -> 1612 | V22: =IF($A22="","",IF(OR(YEAR($A22)<2020,YEAR($A22)>2030),"Podezřelé datum",IF(OR($F22="",$G22=""),"Chybí letiště",IF(OR($H22="",$I22="",$J22="",$K22=""),"Chybí čas",IF(OR($H22>$I22,$I22>$J22,$J22>$K22),"Časy mimo pořadí",IF($M22>$L22,"Air > Block",IF(OR($S22="", $S22<=0),"Chybí sazba","OK"))))))) -> OK
A23: 44153 | B23: ULL | C23: OK-XAI04 | D23: Bristell | E23: ULL | F23: LKSZ | G23: LKSZ | H23: 0.49652778 | I23: 0.5 | J23: 0.6 | K23: 0.60347222 | L23: =IF($A23="","",IF(AND(ISNUMBER($H23),ISNUMBER($K23)),MOD($K23-$H23,1),"")) -> 0.10694444 | M23: =IF($A23="","",IF(AND(ISNUMBER($I23),ISNUMBER($J23)),MOD($J23-$I23,1),"")) -> 0.1 | N23: 3 | O23: Točík Filip | Q23: PIC | S23: 1860 | T23: =IF($A23="","",IF(OR($S23="", $S23<=0, $L23=""),"",ROUND($L23*24*$S23,2))) -> 4774 | V23: =IF($A23="","",IF(OR(YEAR($A23)<2020,YEAR($A23)>2030),"Podezřelé datum",IF(OR($F23="",$G23=""),"Chybí letiště",IF(OR($H23="",$I23="",$J23="",$K23=""),"Chybí čas",IF(OR($H23>$I23,$I23>$J23,$J23>$K23),"Časy mimo pořadí",IF($M23>$L23,"Air > Block",IF(OR($S23="", $S23<=0),"Chybí sazba","OK"))))))) -> OK
A24: 44165 | B24: ULL | C24: OK-XAI04 | D24: Bristell | E24: ULL | F24: LKSZ | G24: LKSZ | H24: 0.5625 | I24: 0.56597222 | J24: 0.64097222 | K24: 0.64444444 | L24: =IF($A24="","",IF(AND(ISNUMBER($H24),ISNUMBER($K24)),MOD($K24-$H24,1),"")) -> 0.081944444 | M24: =IF($A24="","",IF(AND(ISNUMBER($I24),ISNUMBER($J24)),MOD($J24-$I24,1),"")) -> 0.075 | N24: 3 | O24: Točík Filip | Q24: PIC | S24: 1860 | T24: =IF($A24="","",IF(OR($S24="", $S24<=0, $L24=""),"",ROUND($L24*24*$S24,2))) -> 3658 | V24: =IF($A24="","",IF(OR(YEAR($A24)<2020,YEAR($A24)>2030),"Podezřelé datum",IF(OR($F24="",$G24=""),"Chybí letiště",IF(OR($H24="",$I24="",$J24="",$K24=""),"Chybí čas",IF(OR($H24>$I24,$I24>$J24,$J24>$K24),"Časy mimo pořadí",IF($M24>$L24,"Air > Block",IF(OR($S24="", $S24<=0),"Chybí sazba","OK"))))))) -> OK
A25: 44195 | B25: ULL | C25: OK-XAI04 | D25: Bristell | E25: ULL | F25: LKSZ | G25: LKSZ | H25: 0.60277778 | I25: 0.60625 | J25: 0.64791667 | K25: 0.65138889 | L25: =IF($A25="","",IF(AND(ISNUMBER($H25),ISNUMBER($K25)),MOD($K25-$H25,1),"")) -> 0.048611111 | M25: =IF($A25="","",IF(AND(ISNUMBER($I25),ISNUMBER($J25)),MOD($J25-$I25,1),"")) -> 0.041666667 | N25: 3 | O25: Točík Filip | Q25: PIC | S25: 1860 | T25: =IF($A25="","",IF(OR($S25="", $S25<=0, $L25=""),"",ROUND($L25*24*$S25,2))) -> 2170 | V25: =IF($A25="","",IF(OR(YEAR($A25)<2020,YEAR($A25)>2030),"Podezřelé datum",IF(OR($F25="",$G25=""),"Chybí letiště",IF(OR($H25="",$I25="",$J25="",$K25=""),"Chybí čas",IF(OR($H25>$I25,$I25>$J25,$J25>$K25),"Časy mimo pořadí",IF($M25>$L25,"Air > Block",IF(OR($S25="", $S25<=0),"Chybí sazba","OK"))))))) -> OK
A26: 44207 | B26: ULL | C26: OK-XAI04 | D26: Bristell | E26: ULL | F26: LKSZ | G26: LKSZ | H26: 0.54305556 | I26: 0.54652778 | J26: 0.58819444 | K26: 0.59166667 | L26: =IF($A26="","",IF(AND(ISNUMBER($H26),ISNUMBER($K26)),MOD($K26-$H26,1),"")) -> 0.048611111 | M26: =IF($A26="","",IF(AND(ISNUMBER($I26),ISNUMBER($J26)),MOD($J26-$I26,1),"")) -> 0.041666667 | N26: 14 | O26: Točík Filip | Q26: PIC | S26: 1860 | T26: =IF($A26="","",IF(OR($S26="", $S26<=0, $L26=""),"",ROUND($L26*24*$S26,2))) -> 2170 | V26: =IF($A26="","",IF(OR(YEAR($A26)<2020,YEAR($A26)>2030),"Podezřelé datum",IF(OR($F26="",$G26=""),"Chybí letiště",IF(OR($H26="",$I26="",$J26="",$K26=""),"Chybí čas",IF(OR($H26>$I26,$I26>$J26,$J26>$K26),"Časy mimo pořadí",IF($M26>$L26,"Air > Block",IF(OR($S26="", $S26<=0),"Chybí sazba","OK"))))))) -> OK
A27: 44228 | B27: ULL | C27: OK-XAI04 | D27: Bristell | E27: ULL | F27: LKSZ | G27: LKSZ | H27: 0.25972222 | I27: 0.26319444 | J27: 0.32569444 | K27: 0.32916667 | L27: =IF($A27="","",IF(AND(ISNUMBER($H27),ISNUMBER($K27)),MOD($K27-$H27,1),"")) -> 0.069444444 | M27: =IF($A27="","",IF(AND(ISNUMBER($I27),ISNUMBER($J27)),MOD($J27-$I27,1),"")) -> 0.0625 | N27: 10 | O27: Točík Filip | Q27: PIC | S27: 1860 | T27: =IF($A27="","",IF(OR($S27="", $S27<=0, $L27=""),"",ROUND($L27*24*$S27,2))) -> 3100 | V27: =IF($A27="","",IF(OR(YEAR($A27)<2020,YEAR($A27)>2030),"Podezřelé datum",IF(OR($F27="",$G27=""),"Chybí letiště",IF(OR($H27="",$I27="",$J27="",$K27=""),"Chybí čas",IF(OR($H27>$I27,$I27>$J27,$J27>$K27),"Časy mimo pořadí",IF($M27>$L27,"Air > Block",IF(OR($S27="", $S27<=0),"Chybí sazba","OK"))))))) -> OK
A28: 44240 | B28: ULL | C28: OK-XAI04 | D28: Bristell | E28: ULL | F28: LKSZ | G28: LKSZ | H28: 0.46597222 | I28: 0.46944444 | J28: 0.49027778 | K28: 0.49375 | L28: =IF($A28="","",IF(AND(ISNUMBER($H28),ISNUMBER($K28)),MOD($K28-$H28,1),"")) -> 0.027777778 | M28: =IF($A28="","",IF(AND(ISNUMBER($I28),ISNUMBER($J28)),MOD($J28-$I28,1),"")) -> 0.020833333 | N28: 4 | O28: Točík Filip | P28: Vyhnal Libor | Q28: DUAL | S28: 1860 | T28: =IF($A28="","",IF(OR($S28="", $S28<=0, $L28=""),"",ROUND($L28*24*$S28,2))) -> 1240 | V28: =IF($A28="","",IF(OR(YEAR($A28)<2020,YEAR($A28)>2030),"Podezřelé datum",IF(OR($F28="",$G28=""),"Chybí letiště",IF(OR($H28="",$I28="",$J28="",$K28=""),"Chybí čas",IF(OR($H28>$I28,$I28>$J28,$J28>$K28),"Časy mimo pořadí",IF($M28>$L28,"Air > Block",IF(OR($S28="", $S28<=0),"Chybí sazba","OK"))))))) -> OK
A29: 44262 | B29: ULL | C29: OK-XAI04 | D29: Bristell | E29: ULL | F29: LKSZ | G29: LKSZ | H29: 0.43402778 | I29: 0.4375 | J29: 0.55833333 | K29: 0.56180556 | L29: =IF($A29="","",IF(AND(ISNUMBER($H29),ISNUMBER($K29)),MOD($K29-$H29,1),"")) -> 0.12777778 | M29: =IF($A29="","",IF(AND(ISNUMBER($I29),ISNUMBER($J29)),MOD($J29-$I29,1),"")) -> 0.12083333 | N29: 3 | O29: Točík Filip | Q29: PIC | S29: 1860 | T29: =IF($A29="","",IF(OR($S29="", $S29<=0, $L29=""),"",ROUND($L29*24*$S29,2))) -> 5704 | V29: =IF($A29="","",IF(OR(YEAR($A29)<2020,YEAR($A29)>2030),"Podezřelé datum",IF(OR($F29="",$G29=""),"Chybí letiště",IF(OR($H29="",$I29="",$J29="",$K29=""),"Chybí čas",IF(OR($H29>$I29,$I29>$J29,$J29>$K29),"Časy mimo pořadí",IF($M29>$L29,"Air > Block",IF(OR($S29="", $S29<=0),"Chybí sazba","OK"))))))) -> OK
A30: 44316 | B30: ULL | C30: OK-XAI04 | D30: Bristell | E30: ULL | F30: LKSZ | G30: LKSZ | H30: 0.40416667 | I30: 0.40763889 | J30: 0.48263889 | K30: 0.48611111 | L30: =IF($A30="","",IF(AND(ISNUMBER($H30),ISNUMBER($K30)),MOD($K30-$H30,1),"")) -> 0.081944444 | M30: =IF($A30="","",IF(AND(ISNUMBER($I30),ISNUMBER($J30)),MOD($J30-$I30,1),"")) -> 0.075 | N30: 4 | O30: Točík Filip | Q30: PIC | S30: 1860 | T30: =IF($A30="","",IF(OR($S30="", $S30<=0, $L30=""),"",ROUND($L30*24*$S30,2))) -> 3658 | V30: =IF($A30="","",IF(OR(YEAR($A30)<2020,YEAR($A30)>2030),"Podezřelé datum",IF(OR($F30="",$G30=""),"Chybí letiště",IF(OR($H30="",$I30="",$J30="",$K30=""),"Chybí čas",IF(OR($H30>$I30,$I30>$J30,$J30>$K30),"Časy mimo pořadí",IF($M30>$L30,"Air > Block",IF(OR($S30="", $S30<=0),"Chybí sazba","OK"))))))) -> OK
A31: 44340 | B31: ULL | C31: OK-XAI04 | D31: Bristell | E31: ULL | F31: LKSZ | G31: LKSZ | H31: 0.49166667 | I31: 0.49513889 | J31: 0.51597222 | K31: 0.51944444 | L31: =IF($A31="","",IF(AND(ISNUMBER($H31),ISNUMBER($K31)),MOD($K31-$H31,1),"")) -> 0.027777778 | M31: =IF($A31="","",IF(AND(ISNUMBER($I31),ISNUMBER($J31)),MOD($J31-$I31,1),"")) -> 0.020833333 | N31: 3 | O31: Točík Filip | P31: Šindelář Petr | Q31: DUAL | S31: 1860 | T31: =IF($A31="","",IF(OR($S31="", $S31<=0, $L31=""),"",ROUND($L31*24*$S31,2))) -> 1240 | V31: =IF($A31="","",IF(OR(YEAR($A31)<2020,YEAR($A31)>2030),"Podezřelé datum",IF(OR($F31="",$G31=""),"Chybí letiště",IF(OR($H31="",$I31="",$J31="",$K31=""),"Chybí čas",IF(OR($H31>$I31,$I31>$J31,$J31>$K31),"Časy mimo pořadí",IF($M31>$L31,"Air > Block",IF(OR($S31="", $S31<=0),"Chybí sazba","OK"))))))) -> OK
A32: 44340 | B32: ULL | C32: OK-XAI04 | D32: Bristell | E32: ULL | F32: LKSZ | G32: LKSZ | H32: 0.54305556 | I32: 0.54652778 | J32: 0.56736111 | K32: 0.57083333 | L32: =IF($A32="","",IF(AND(ISNUMBER($H32),ISNUMBER($K32)),MOD($K32-$H32,1),"")) -> 0.027777778 | M32: =IF($A32="","",IF(AND(ISNUMBER($I32),ISNUMBER($J32)),MOD($J32-$I32,1),"")) -> 0.020833333 | N32: 8 | O32: Točík Filip | Q32: PIC | S32: 1860 | T32: =IF($A32="","",IF(OR($S32="", $S32<=0, $L32=""),"",ROUND($L32*24*$S32,2))) -> 1240 | V32: =IF($A32="","",IF(OR(YEAR($A32)<2020,YEAR($A32)>2030),"Podezřelé datum",IF(OR($F32="",$G32=""),"Chybí letiště",IF(OR($H32="",$I32="",$J32="",$K32=""),"Chybí čas",IF(OR($H32>$I32,$I32>$J32,$J32>$K32),"Časy mimo pořadí",IF($M32>$L32,"Air > Block",IF(OR($S32="", $S32<=0),"Chybí sazba","OK"))))))) -> OK
A33: 44352 | B33: ULL | C33: OK-XAI04 | D33: Bristell | E33: ULL | F33: LKSZ | G33: LKMO | H33: 0.37083333 | I33: 0.37430556 | J33: 0.38680556 | K33: 0.39027778 | L33: =IF($A33="","",IF(AND(ISNUMBER($H33),ISNUMBER($K33)),MOD($K33-$H33,1),"")) -> 0.019444444 | M33: =IF($A33="","",IF(AND(ISNUMBER($I33),ISNUMBER($J33)),MOD($J33-$I33,1),"")) -> 0.0125 | N33: 1 | O33: Točík Filip | Q33: PIC | R33: LKSZ-LKMO | S33: 1860 | T33: =IF($A33="","",IF(OR($S33="", $S33<=0, $L33=""),"",ROUND($L33*24*$S33,2))) -> 868 | V33: =IF($A33="","",IF(OR(YEAR($A33)<2020,YEAR($A33)>2030),"Podezřelé datum",IF(OR($F33="",$G33=""),"Chybí letiště",IF(OR($H33="",$I33="",$J33="",$K33=""),"Chybí čas",IF(OR($H33>$I33,$I33>$J33,$J33>$K33),"Časy mimo pořadí",IF($M33>$L33,"Air > Block",IF(OR($S33="", $S33<=0),"Chybí sazba","OK"))))))) -> OK
A34: 44352 | B34: ULL | C34: OK-XAI04 | D34: Bristell | E34: ULL | F34: LKMO | G34: LKSZ | H34: 0.43125 | I34: 0.43472222 | J34: 0.44722222 | K34: 0.45069444 | L34: =IF($A34="","",IF(AND(ISNUMBER($H34),ISNUMBER($K34)),MOD($K34-$H34,1),"")) -> 0.019444444 | M34: =IF($A34="","",IF(AND(ISNUMBER($I34),ISNUMBER($J34)),MOD($J34-$I34,1),"")) -> 0.0125 | N34: 1 | O34: Točík Filip | Q34: PIC | R34: LKMO-LKSZ | S34: 1860 | T34: =IF($A34="","",IF(OR($S34="", $S34<=0, $L34=""),"",ROUND($L34*24*$S34,2))) -> 868 | V34: =IF($A34="","",IF(OR(YEAR($A34)<2020,YEAR($A34)>2030),"Podezřelé datum",IF(OR($F34="",$G34=""),"Chybí letiště",IF(OR($H34="",$I34="",$J34="",$K34=""),"Chybí čas",IF(OR($H34>$I34,$I34>$J34,$J34>$K34),"Časy mimo pořadí",IF($M34>$L34,"Air > Block",IF(OR($S34="", $S34<=0),"Chybí sazba","OK"))))))) -> OK
A35: 44358 | B35: ULL | C35: OK-XAI04 | D35: Bristell | E35: ULL | F35: LKSZ | G35: LKCHRI | H35: 0.56736111 | I35: 0.57083333 | J35: 0.5875 | K35: 0.59097222 | L35: =IF($A35="","",IF(AND(ISNUMBER($H35),ISNUMBER($K35)),MOD($K35-$H35,1),"")) -> 0.023611111 | M35: =IF($A35="","",IF(AND(ISNUMBER($I35),ISNUMBER($J35)),MOD($J35-$I35,1),"")) -> 0.016666667 | N35: 1 | O35: Točík Filip | Q35: PIC | R35: LKSZ-LKCHRI | S35: 1860 | T35: =IF($A35="","",IF(OR($S35="", $S35<=0, $L35=""),"",ROUND($L35*24*$S35,2))) -> 1054 | V35: =IF($A35="","",IF(OR(YEAR($A35)<2020,YEAR($A35)>2030),"Podezřelé datum",IF(OR($F35="",$G35=""),"Chybí letiště",IF(OR($H35="",$I35="",$J35="",$K35=""),"Chybí čas",IF(OR($H35>$I35,$I35>$J35,$J35>$K35),"Časy mimo pořadí",IF($M35>$L35,"Air > Block",IF(OR($S35="", $S35<=0),"Chybí sazba","OK"))))))) -> OK
A36: 44358 | B36: ULL | C36: OK-XAI04 | D36: Bristell | E36: ULL | F36: LKCHRI | G36: LKSZ | H36: 0.60486111 | I36: 0.60833333 | J36: 0.62916667 | K36: 0.63263889 | L36: =IF($A36="","",IF(AND(ISNUMBER($H36),ISNUMBER($K36)),MOD($K36-$H36,1),"")) -> 0.027777778 | M36: =IF($A36="","",IF(AND(ISNUMBER($I36),ISNUMBER($J36)),MOD($J36-$I36,1),"")) -> 0.020833333 | N36: 1 | O36: Točík Filip | Q36: PIC | R36: LKCHRI-LKSZ | S36: 1860 | T36: =IF($A36="","",IF(OR($S36="", $S36<=0, $L36=""),"",ROUND($L36*24*$S36,2))) -> 1240 | V36: =IF($A36="","",IF(OR(YEAR($A36)<2020,YEAR($A36)>2030),"Podezřelé datum",IF(OR($F36="",$G36=""),"Chybí letiště",IF(OR($H36="",$I36="",$J36="",$K36=""),"Chybí čas",IF(OR($H36>$I36,$I36>$J36,$J36>$K36),"Časy mimo pořadí",IF($M36>$L36,"Air > Block",IF(OR($S36="", $S36<=0),"Chybí sazba","OK"))))))) -> OK
A37: 44375 | B37: ULL | C37: OK-XAI04 | D37: Bristell | E37: ULL | F37: LKSZ | G37: LKSZ | H37: 0.69097222 | I37: 0.69444444 | J37: 0.77361111 | K37: 0.77708333 | L37: =IF($A37="","",IF(AND(ISNUMBER($H37),ISNUMBER($K37)),MOD($K37-$H37,1),"")) -> 0.086111111 | M37: =IF($A37="","",IF(AND(ISNUMBER($I37),ISNUMBER($J37)),MOD($J37-$I37,1),"")) -> 0.079166667 | N37: 2 | O37: Točík Filip | Q37: PIC | R37: LKSZ-LKHD-LKSZ | S37: 1860 | T37: =IF($A37="","",IF(OR($S37="", $S37<=0, $L37=""),"",ROUND($L37*24*$S37,2))) -> 3844 | V37: =IF($A37="","",IF(OR(YEAR($A37)<2020,YEAR($A37)>2030),"Podezřelé datum",IF(OR($F37="",$G37=""),"Chybí letiště",IF(OR($H37="",$I37="",$J37="",$K37=""),"Chybí čas",IF(OR($H37>$I37,$I37>$J37,$J37>$K37),"Časy mimo pořadí",IF($M37>$L37,"Air > Block",IF(OR($S37="", $S37<=0),"Chybí sazba","OK"))))))) -> OK
A38: 44379 | B38: ULL | C38: OK-XAI04 | D38: Bristell | E38: ULL | F38: LKSZ | G38: LKSZ | H38: 0.67638889 | I38: 0.67986111 | J38: 0.69652778 | K38: 0.7 | L38: =IF($A38="","",IF(AND(ISNUMBER($H38),ISNUMBER($K38)),MOD($K38-$H38,1),"")) -> 0.023611111 | M38: =IF($A38="","",IF(AND(ISNUMBER($I38),ISNUMBER($J38)),MOD($J38-$I38,1),"")) -> 0.016666667 | N38: 2 | O38: Točík Filip | Q38: PIC | S38: 1860 | T38: =IF($A38="","",IF(OR($S38="", $S38<=0, $L38=""),"",ROUND($L38*24*$S38,2))) -> 1054 | V38: =IF($A38="","",IF(OR(YEAR($A38)<2020,YEAR($A38)>2030),"Podezřelé datum",IF(OR($F38="",$G38=""),"Chybí letiště",IF(OR($H38="",$I38="",$J38="",$K38=""),"Chybí čas",IF(OR($H38>$I38,$I38>$J38,$J38>$K38),"Časy mimo pořadí",IF($M38>$L38,"Air > Block",IF(OR($S38="", $S38<=0),"Chybí sazba","OK"))))))) -> OK
A39: 44384 | B39: ULL | C39: OK-XAI04 | D39: Bristell | E39: ULL | F39: LKSZ | G39: LKSZ | H39: 0.60416667 | I39: 0.60763889 | J39: 0.67013889 | K39: 0.67361111 | L39: =IF($A39="","",IF(AND(ISNUMBER($H39),ISNUMBER($K39)),MOD($K39-$H39,1),"")) -> 0.069444444 | M39: =IF($A39="","",IF(AND(ISNUMBER($I39),ISNUMBER($J39)),MOD($J39-$I39,1),"")) -> 0.0625 | N39: 4 | O39: Točík Filip | Q39: PIC | S39: 1860 | T39: =IF($A39="","",IF(OR($S39="", $S39<=0, $L39=""),"",ROUND($L39*24*$S39,2))) -> 3100 | V39: =IF($A39="","",IF(OR(YEAR($A39)<2020,YEAR($A39)>2030),"Podezřelé datum",IF(OR($F39="",$G39=""),"Chybí letiště",IF(OR($H39="",$I39="",$J39="",$K39=""),"Chybí čas",IF(OR($H39>$I39,$I39>$J39,$J39>$K39),"Časy mimo pořadí",IF($M39>$L39,"Air > Block",IF(OR($S39="", $S39<=0),"Chybí sazba","OK"))))))) -> OK
A40: 44387 | B40: ULL | C40: OK-XAI04 | D40: Bristell | E40: ULL | F40: LKSZ | G40: LKSZ | H40: 0.75 | I40: 0.75347222 | J40: 0.77430556 | K40: 0.77777778 | L40: =IF($A40="","",IF(AND(ISNUMBER($H40),ISNUMBER($K40)),MOD($K40-$H40,1),"")) -> 0.027777778 | M40: =IF($A40="","",IF(AND(ISNUMBER($I40),ISNUMBER($J40)),MOD($J40-$I40,1),"")) -> 0.020833333 | N40: 1 | O40: Točík Filip | Q40: PIC | S40: 1860 | T40: =IF($A40="","",IF(OR($S40="", $S40<=0, $L40=""),"",ROUND($L40*24*$S40,2))) -> 1240 | V40: =IF($A40="","",IF(OR(YEAR($A40)<2020,YEAR($A40)>2030),"Podezřelé datum",IF(OR($F40="",$G40=""),"Chybí letiště",IF(OR($H40="",$I40="",$J40="",$K40=""),"Chybí čas",IF(OR($H40>$I40,$I40>$J40,$J40>$K40),"Časy mimo pořadí",IF($M40>$L40,"Air > Block",IF(OR($S40="", $S40<=0),"Chybí sazba","OK"))))))) -> OK
...

Sheet Souhrny
A1: Souhrny
A3: Rok | B3: Letů | C3: Celkem | D3: PIC | E3: PIC ULL | F3: PIC EASA | G3: DUAL | H3: Instruktor | I3: Safety Pilot | J3: ULL | K3: EASA | L3: Starty | M3: Náklady Kč
A4: 2020 | B4: =COUNTIFS('Zápisník letů'!$A$2:$A$1018,">="&DATE($A4,1,1),'Zápisník letů'!$A$2:$A$1018,"<"&DATE($A4+1,1,1)) -> 24 | C4: =SUMIFS('Zápisník letů'!$L$2:$L$1018,'Zápisník letů'!$A$2:$A$1018,">="&DATE($A4,1,1),'Zápisník letů'!$A$2:$A$1018,"<"&DATE($A4+1,1,1)) -> 0.99583333 | D4: =SUMIFS('Zápisník letů'!$L$2:$L$1018,'Zápisník letů'!$A$2:$A$1018,">="&DATE($A4,1,1),'Zápisník letů'!$A$2:$A$1018,"<"&DATE($A4+1,1,1),'Zápisník letů'!$Q$2:$Q$1018,"PIC") -> 0.80694444 | E4: =SUMIFS('Zápisník letů'!$L$2:$L$1018,'Zápisník letů'!$A$2:$A$1018,">="&DATE($A4,1,1),'Zápisník letů'!$A$2:$A$1018,"<"&DATE($A4+1,1,1),'Zápisník letů'!$Q$2:$Q$1018,"PIC",'Zápisník letů'!$B$2:$B$1018,"ULL") -> 0.80694444 | F4: =SUMIFS('Zápisník letů'!$L$2:$L$1018,'Zápisník letů'!$A$2:$A$1018,">="&DATE($A4,1,1),'Zápisník letů'!$A$2:$A$1018,"<"&DATE($A4+1,1,1),'Zápisník letů'!$Q$2:$Q$1018,"PIC",'Zápisník letů'!$B$2:$B$1018,"EASA") -> 0 | G4: =SUMIFS('Zápisník letů'!$L$2:$L$1018,'Zápisník letů'!$A$2:$A$1018,">="&DATE($A4,1,1),'Zápisník letů'!$A$2:$A$1018,"<"&DATE($A4+1,1,1),'Zápisník letů'!$Q$2:$Q$1018,"DUAL") -> 0.18888889 | H4: =SUMIFS('Zápisník letů'!$L$2:$L$1018,'Zápisník letů'!$A$2:$A$1018,">="&DATE($A4,1,1),'Zápisník letů'!$A$2:$A$1018,"<"&DATE($A4+1,1,1),'Zápisník letů'!$Q$2:$Q$1018,"INSTRUKTOR") -> 0 | I4: =SUMIFS('Zápisník letů'!$L$2:$L$1018,'Zápisník letů'!$A$2:$A$1018,">="&DATE($A4,1,1),'Zápisník letů'!$A$2:$A$1018,"<"&DATE($A4+1,1,1),'Zápisník letů'!$Q$2:$Q$1018,"SAFETY PILOT") -> 0 | J4: =SUMIFS('Zápisník letů'!$L$2:$L$1018,'Zápisník letů'!$A$2:$A$1018,">="&DATE($A4,1,1),'Zápisník letů'!$A$2:$A$1018,"<"&DATE($A4+1,1,1),'Zápisník letů'!$B$2:$B$1018,"ULL") -> 0.99583333 | K4: =SUMIFS('Zápisník letů'!$L$2:$L$1018,'Zápisník letů'!$A$2:$A$1018,">="&DATE($A4,1,1),'Zápisník letů'!$A$2:$A$1018,"<"&DATE($A4+1,1,1),'Zápisník letů'!$B$2:$B$1018,"EASA") -> 0 | L4: =SUMIFS('Zápisník letů'!$N$2:$N$1018,'Zápisník letů'!$A$2:$A$1018,">="&DATE($A4,1,1),'Zápisník letů'!$A$2:$A$1018,"<"&DATE($A4+1,1,1)) -> 86 | M4: =SUMIFS('Zápisník letů'!$T$2:$T$1018,'Zápisník letů'!$A$2:$A$1018,">="&DATE($A4,1,1),'Zápisník letů'!$A$2:$A$1018,"<"&DATE($A4+1,1,1)) -> 44454
A5: 2021 | B5: =COUNTIFS('Zápisník letů'!$A$2:$A$1018,">="&DATE($A5,1,1),'Zápisník letů'!$A$2:$A$1018,"<"&DATE($A5+1,1,1)) -> 39 | C5: =SUMIFS('Zápisník letů'!$L$2:$L$1018,'Zápisník letů'!$A$2:$A$1018,">="&DATE($A5,1,1),'Zápisník letů'!$A$2:$A$1018,"<"&DATE($A5+1,1,1)) -> 1.8076389 | D5: =SUMIFS('Zápisník letů'!$L$2:$L$1018,'Zápisník letů'!$A$2:$A$1018,">="&DATE($A5,1,1),'Zápisník letů'!$A$2:$A$1018,"<"&DATE($A5+1,1,1),'Zápisník letů'!$Q$2:$Q$1018,"PIC") -> 1.5145833 | E5: =SUMIFS('Zápisník letů'!$L$2:$L$1018,'Zápisník letů'!$A$2:$A$1018,">="&DATE($A5,1,1),'Zápisník letů'!$A$2:$A$1018,"<"&DATE($A5+1,1,1),'Zápisník letů'!$Q$2:$Q$1018,"PIC",'Zápisník letů'!$B$2:$B$1018,"ULL") -> 1.5020833 | F5: =SUMIFS('Zápisník letů'!$L$2:$L$1018,'Zápisník letů'!$A$2:$A$1018,">="&DATE($A5,1,1),'Zápisník letů'!$A$2:$A$1018,"<"&DATE($A5+1,1,1),'Zápisník letů'!$Q$2:$Q$1018,"PIC",'Zápisník letů'!$B$2:$B$1018,"EASA") -> 0.0125 | G5: =SUMIFS('Zápisník letů'!$L$2:$L$1018,'Zápisník letů'!$A$2:$A$1018,">="&DATE($A5,1,1),'Zápisník letů'!$A$2:$A$1018,"<"&DATE($A5+1,1,1),'Zápisník letů'!$Q$2:$Q$1018,"DUAL") -> 0.29305556 | H5: =SUMIFS('Zápisník letů'!$L$2:$L$1018,'Zápisník letů'!$A$2:$A$1018,">="&DATE($A5,1,1),'Zápisník letů'!$A$2:$A$1018,"<"&DATE($A5+1,1,1),'Zápisník letů'!$Q$2:$Q$1018,"INSTRUKTOR") -> 0 | I5: =SUMIFS('Zápisník letů'!$L$2:$L$1018,'Zápisník letů'!$A$2:$A$1018,">="&DATE($A5,1,1),'Zápisník letů'!$A$2:$A$1018,"<"&DATE($A5+1,1,1),'Zápisník letů'!$Q$2:$Q$1018,"SAFETY PILOT") -> 0 | J5: =SUMIFS('Zápisník letů'!$L$2:$L$1018,'Zápisník letů'!$A$2:$A$1018,">="&DATE($A5,1,1),'Zápisník letů'!$A$2:$A$1018,"<"&DATE($A5+1,1,1),'Zápisník letů'!$B$2:$B$1018,"ULL") -> 1.5576389 | K5: =SUMIFS('Zápisník letů'!$L$2:$L$1018,'Zápisník letů'!$A$2:$A$1018,">="&DATE($A5,1,1),'Zápisník letů'!$A$2:$A$1018,"<"&DATE($A5+1,1,1),'Zápisník letů'!$B$2:$B$1018,"EASA") -> 0.25 | L5: =SUMIFS('Zápisník letů'!$N$2:$N$1018,'Zápisník letů'!$A$2:$A$1018,">="&DATE($A5,1,1),'Zápisník letů'!$A$2:$A$1018,"<"&DATE($A5+1,1,1)) -> 142 | M5: =SUMIFS('Zápisník letů'!$T$2:$T$1018,'Zápisník letů'!$A$2:$A$1018,">="&DATE($A5,1,1),'Zápisník letů'!$A$2:$A$1018,"<"&DATE($A5+1,1,1)) -> 87137
A6: 2022 | B6: =COUNTIFS('Zápisník letů'!$A$2:$A$1018,">="&DATE($A6,1,1),'Zápisník letů'!$A$2:$A$1018,"<"&DATE($A6+1,1,1)) -> 26 | C6: =SUMIFS('Zápisník letů'!$L$2:$L$1018,'Zápisník letů'!$A$2:$A$1018,">="&DATE($A6,1,1),'Zápisník letů'!$A$2:$A$1018,"<"&DATE($A6+1,1,1)) -> 1.9847222 | D6: =SUMIFS('Zápisník letů'!$L$2:$L$1018,'Zápisník letů'!$A$2:$A$1018,">="&DATE($A6,1,1),'Zápisník letů'!$A$2:$A$1018,"<"&DATE($A6+1,1,1),'Zápisník letů'!$Q$2:$Q$1018,"PIC") -> 1.7159722 | E6: =SUMIFS('Zápisník letů'!$L$2:$L$1018,'Zápisník letů'!$A$2:$A$1018,">="&DATE($A6,1,1),'Zápisník letů'!$A$2:$A$1018,"<"&DATE($A6+1,1,1),'Zápisník letů'!$Q$2:$Q$1018,"PIC",'Zápisník letů'!$B$2:$B$1018,"ULL") -> 1.6291667 | F6: =SUMIFS('Zápisník letů'!$L$2:$L$1018,'Zápisník letů'!$A$2:$A$1018,">="&DATE($A6,1,1),'Zápisník letů'!$A$2:$A$1018,"<"&DATE($A6+1,1,1),'Zápisník letů'!$Q$2:$Q$1018,"PIC",'Zápisník letů'!$B$2:$B$1018,"EASA") -> 0.086805556 | G6: =SUMIFS('Zápisník letů'!$L$2:$L$1018,'Zápisník letů'!$A$2:$A$1018,">="&DATE($A6,1,1),'Zápisník letů'!$A$2:$A$1018,"<"&DATE($A6+1,1,1),'Zápisník letů'!$Q$2:$Q$1018,"DUAL") -> 0.26875 | H6: =SUMIFS('Zápisník letů'!$L$2:$L$1018,'Zápisník letů'!$A$2:$A$1018,">="&DATE($A6,1,1),'Zápisník letů'!$A$2:$A$1018,"<"&DATE($A6+1,1,1),'Zápisník letů'!$Q$2:$Q$1018,"INSTRUKTOR") -> 0 | I6: =SUMIFS('Zápisník letů'!$L$2:$L$1018,'Zápisník letů'!$A$2:$A$1018,">="&DATE($A6,1,1),'Zápisník letů'!$A$2:$A$1018,"<"&DATE($A6+1,1,1),'Zápisník letů'!$Q$2:$Q$1018,"SAFETY PILOT") -> 0 | J6: =SUMIFS('Zápisník letů'!$L$2:$L$1018,'Zápisník letů'!$A$2:$A$1018,">="&DATE($A6,1,1),'Zápisník letů'!$A$2:$A$1018,"<"&DATE($A6+1,1,1),'Zápisník letů'!$B$2:$B$1018,"ULL") -> 1.6291667 | K6: =SUMIFS('Zápisník letů'!$L$2:$L$1018,'Zápisník letů'!$A$2:$A$1018,">="&DATE($A6,1,1),'Zápisník letů'!$A$2:$A$1018,"<"&DATE($A6+1,1,1),'Zápisník letů'!$B$2:$B$1018,"EASA") -> 0.35555556 | L6: =SUMIFS('Zápisník letů'!$N$2:$N$1018,'Zápisník letů'!$A$2:$A$1018,">="&DATE($A6,1,1),'Zápisník letů'!$A$2:$A$1018,"<"&DATE($A6+1,1,1)) -> 89 | M6: =SUMIFS('Zápisník letů'!$T$2:$T$1018,'Zápisník letů'!$A$2:$A$1018,">="&DATE($A6,1,1),'Zápisník letů'!$A$2:$A$1018,"<"&DATE($A6+1,1,1)) -> 111942
A7: 2023 | B7: =COUNTIFS('Zápisník letů'!$A$2:$A$1018,">="&DATE($A7,1,1),'Zápisník letů'!$A$2:$A$1018,"<"&DATE($A7+1,1,1)) -> 24 | C7: =SUMIFS('Zápisník letů'!$L$2:$L$1018,'Zápisník letů'!$A$2:$A$1018,">="&DATE($A7,1,1),'Zápisník letů'!$A$2:$A$1018,"<"&DATE($A7+1,1,1)) -> 1.6263889 | D7: =SUMIFS('Zápisník letů'!$L$2:$L$1018,'Zápisník letů'!$A$2:$A$1018,">="&DATE($A7,1,1),'Zápisník letů'!$A$2:$A$1018,"<"&DATE($A7+1,1,1),'Zápisník letů'!$Q$2:$Q$1018,"PIC") -> 1.5305556 | E7: =SUMIFS('Zápisník letů'!$L$2:$L$1018,'Zápisník letů'!$A$2:$A$1018,">="&DATE($A7,1,1),'Zápisník letů'!$A$2:$A$1018,"<"&DATE($A7+1,1,1),'Zápisník letů'!$Q$2:$Q$1018,"PIC",'Zápisník letů'!$B$2:$B$1018,"ULL") -> 1.4888889 | F7: =SUMIFS('Zápisník letů'!$L$2:$L$1018,'Zápisník letů'!$A$2:$A$1018,">="&DATE($A7,1,1),'Zápisník letů'!$A$2:$A$1018,"<"&DATE($A7+1,1,1),'Zápisník letů'!$Q$2:$Q$1018,"PIC",'Zápisník letů'!$B$2:$B$1018,"EASA") -> 0.041666667 | G7: =SUMIFS('Zápisník letů'!$L$2:$L$1018,'Zápisník letů'!$A$2:$A$1018,">="&DATE($A7,1,1),'Zápisník letů'!$A$2:$A$1018,"<"&DATE($A7+1,1,1),'Zápisník letů'!$Q$2:$Q$1018,"DUAL") -> 0.095833333 | H7: =SUMIFS('Zápisník letů'!$L$2:$L$1018,'Zápisník letů'!$A$2:$A$1018,">="&DATE($A7,1,1),'Zápisník letů'!$A$2:$A$1018,"<"&DATE($A7+1,1,1),'Zápisník letů'!$Q$2:$Q$1018,"INSTRUKTOR") -> 0 | I7: =SUMIFS('Zápisník letů'!$L$2:$L$1018,'Zápisník letů'!$A$2:$A$1018,">="&DATE($A7,1,1),'Zápisník letů'!$A$2:$A$1018,"<"&DATE($A7+1,1,1),'Zápisník letů'!$Q$2:$Q$1018,"SAFETY PILOT") -> 0 | J7: =SUMIFS('Zápisník letů'!$L$2:$L$1018,'Zápisník letů'!$A$2:$A$1018,">="&DATE($A7,1,1),'Zápisník letů'!$A$2:$A$1018,"<"&DATE($A7+1,1,1),'Zápisník letů'!$B$2:$B$1018,"ULL") -> 1.5694444 | K7: =SUMIFS('Zápisník letů'!$L$2:$L$1018,'Zápisník letů'!$A$2:$A$1018,">="&DATE($A7,1,1),'Zápisník letů'!$A$2:$A$1018,"<"&DATE($A7+1,1,1),'Zápisník letů'!$B$2:$B$1018,"EASA") -> 0.056944444 | L7: =SUMIFS('Zápisník letů'!$N$2:$N$1018,'Zápisník letů'!$A$2:$A$1018,">="&DATE($A7,1,1),'Zápisník letů'!$A$2:$A$1018,"<"&DATE($A7+1,1,1)) -> 70 | M7: =SUMIFS('Zápisník letů'!$T$2:$T$1018,'Zápisník letů'!$A$2:$A$1018,">="&DATE($A7,1,1),'Zápisník letů'!$A$2:$A$1018,"<"&DATE($A7+1,1,1)) -> 90959.32
A8: 2024 | B8: =COUNTIFS('Zápisník letů'!$A$2:$A$1018,">="&DATE($A8,1,1),'Zápisník letů'!$A$2:$A$1018,"<"&DATE($A8+1,1,1)) -> 37 | C8: =SUMIFS('Zápisník letů'!$L$2:$L$1018,'Zápisník letů'!$A$2:$A$1018,">="&DATE($A8,1,1),'Zápisník letů'!$A$2:$A$1018,"<"&DATE($A8+1,1,1)) -> 2.0076389 | D8: =SUMIFS('Zápisník letů'!$L$2:$L$1018,'Zápisník letů'!$A$2:$A$1018,">="&DATE($A8,1,1),'Zápisník letů'!$A$2:$A$1018,"<"&DATE($A8+1,1,1),'Zápisník letů'!$Q$2:$Q$1018,"PIC") -> 1.4993056 | E8: =SUMIFS('Zápisník letů'!$L$2:$L$1018,'Zápisník letů'!$A$2:$A$1018,">="&DATE($A8,1,1),'Zápisník letů'!$A$2:$A$1018,"<"&DATE($A8+1,1,1),'Zápisník letů'!$Q$2:$Q$1018,"PIC",'Zápisník letů'!$B$2:$B$1018,"ULL") -> 1.3847222 | F8: =SUMIFS('Zápisník letů'!$L$2:$L$1018,'Zápisník letů'!$A$2:$A$1018,">="&DATE($A8,1,1),'Zápisník letů'!$A$2:$A$1018,"<"&DATE($A8+1,1,1),'Zápisník letů'!$Q$2:$Q$1018,"PIC",'Zápisník letů'!$B$2:$B$1018,"EASA") -> 0.11458333 | G8: =SUMIFS('Zápisník letů'!$L$2:$L$1018,'Zápisník letů'!$A$2:$A$1018,">="&DATE($A8,1,1),'Zápisník letů'!$A$2:$A$1018,"<"&DATE($A8+1,1,1),'Zápisník letů'!$Q$2:$Q$1018,"DUAL") -> 0.42361111 | H8: =SUMIFS('Zápisník letů'!$L$2:$L$1018,'Zápisník letů'!$A$2:$A$1018,">="&DATE($A8,1,1),'Zápisník letů'!$A$2:$A$1018,"<"&DATE($A8+1,1,1),'Zápisník letů'!$Q$2:$Q$1018,"INSTRUKTOR") -> 0 | I8: =SUMIFS('Zápisník letů'!$L$2:$L$1018,'Zápisník letů'!$A$2:$A$1018,">="&DATE($A8,1,1),'Zápisník letů'!$A$2:$A$1018,"<"&DATE($A8+1,1,1),'Zápisník letů'!$Q$2:$Q$1018,"SAFETY PILOT") -> 0.084722222 | J8: =SUMIFS('Zápisník letů'!$L$2:$L$1018,'Zápisník letů'!$A$2:$A$1018,">="&DATE($A8,1,1),'Zápisník letů'!$A$2:$A$1018,"<"&DATE($A8+1,1,1),'Zápisník letů'!$B$2:$B$1018,"ULL") -> 1.5013889 | K8: =SUMIFS('Zápisník letů'!$L$2:$L$1018,'Zápisník letů'!$A$2:$A$1018,">="&DATE($A8,1,1),'Zápisník letů'!$A$2:$A$1018,"<"&DATE($A8+1,1,1),'Zápisník letů'!$B$2:$B$1018,"EASA") -> 0.50625 | L8: =SUMIFS('Zápisník letů'!$N$2:$N$1018,'Zápisník letů'!$A$2:$A$1018,">="&DATE($A8,1,1),'Zápisník letů'!$A$2:$A$1018,"<"&DATE($A8+1,1,1)) -> 103 | M8: =SUMIFS('Zápisník letů'!$T$2:$T$1018,'Zápisník letů'!$A$2:$A$1018,">="&DATE($A8,1,1),'Zápisník letů'!$A$2:$A$1018,"<"&DATE($A8+1,1,1)) -> 122551.67
A9: 2025 | B9: =COUNTIFS('Zápisník letů'!$A$2:$A$1018,">="&DATE($A9,1,1),'Zápisník letů'!$A$2:$A$1018,"<"&DATE($A9+1,1,1)) -> 30 | C9: =SUMIFS('Zápisník letů'!$L$2:$L$1018,'Zápisník letů'!$A$2:$A$1018,">="&DATE($A9,1,1),'Zápisník letů'!$A$2:$A$1018,"<"&DATE($A9+1,1,1)) -> 1.9472222 | D9: =SUMIFS('Zápisník letů'!$L$2:$L$1018,'Zápisník letů'!$A$2:$A$1018,">="&DATE($A9,1,1),'Zápisník letů'!$A$2:$A$1018,"<"&DATE($A9+1,1,1),'Zápisník letů'!$Q$2:$Q$1018,"PIC") -> 1.4763889 | E9: =SUMIFS('Zápisník letů'!$L$2:$L$1018,'Zápisník letů'!$A$2:$A$1018,">="&DATE($A9,1,1),'Zápisník letů'!$A$2:$A$1018,"<"&DATE($A9+1,1,1),'Zápisník letů'!$Q$2:$Q$1018,"PIC",'Zápisník letů'!$B$2:$B$1018,"ULL") -> 1.4555556 | F9: =SUMIFS('Zápisník letů'!$L$2:$L$1018,'Zápisník letů'!$A$2:$A$1018,">="&DATE($A9,1,1),'Zápisník letů'!$A$2:$A$1018,"<"&DATE($A9+1,1,1),'Zápisník letů'!$Q$2:$Q$1018,"PIC",'Zápisník letů'!$B$2:$B$1018,"EASA") -> 0.020833333 | G9: =SUMIFS('Zápisník letů'!$L$2:$L$1018,'Zápisník letů'!$A$2:$A$1018,">="&DATE($A9,1,1),'Zápisník letů'!$A$2:$A$1018,"<"&DATE($A9+1,1,1),'Zápisník letů'!$Q$2:$Q$1018,"DUAL") -> 0.067361111 | H9: =SUMIFS('Zápisník letů'!$L$2:$L$1018,'Zápisník letů'!$A$2:$A$1018,">="&DATE($A9,1,1),'Zápisník letů'!$A$2:$A$1018,"<"&DATE($A9+1,1,1),'Zápisník letů'!$Q$2:$Q$1018,"INSTRUKTOR") -> 0 | I9: =SUMIFS('Zápisník letů'!$L$2:$L$1018,'Zápisník letů'!$A$2:$A$1018,">="&DATE($A9,1,1),'Zápisník letů'!$A$2:$A$1018,"<"&DATE($A9+1,1,1),'Zápisník letů'!$Q$2:$Q$1018,"SAFETY PILOT") -> 0.40347222 | J9: =SUMIFS('Zápisník letů'!$L$2:$L$1018,'Zápisník letů'!$A$2:$A$1018,">="&DATE($A9,1,1),'Zápisník letů'!$A$2:$A$1018,"<"&DATE($A9+1,1,1),'Zápisník letů'!$B$2:$B$1018,"ULL") -> 1.7020833 | K9: =SUMIFS('Zápisník letů'!$L$2:$L$1018,'Zápisník letů'!$A$2:$A$1018,">="&DATE($A9,1,1),'Zápisník letů'!$A$2:$A$1018,"<"&DATE($A9+1,1,1),'Zápisník letů'!$B$2:$B$1018,"EASA") -> 0.24513889 | L9: =SUMIFS('Zápisník letů'!$N$2:$N$1018,'Zápisník letů'!$A$2:$A$1018,">="&DATE($A9,1,1),'Zápisník letů'!$A$2:$A$1018,"<"&DATE($A9+1,1,1)) -> 57 | M9: =SUMIFS('Zápisník letů'!$T$2:$T$1018,'Zápisník letů'!$A$2:$A$1018,">="&DATE($A9,1,1),'Zápisník letů'!$A$2:$A$1018,"<"&DATE($A9+1,1,1)) -> 130158.67
A10: 2026 | B10: =COUNTIFS('Zápisník letů'!$A$2:$A$1018,">="&DATE($A10,1,1),'Zápisník letů'!$A$2:$A$1018,"<"&DATE($A10+1,1,1)) -> 15 | C10: =SUMIFS('Zápisník letů'!$L$2:$L$1018,'Zápisník letů'!$A$2:$A$1018,">="&DATE($A10,1,1),'Zápisník letů'!$A$2:$A$1018,"<"&DATE($A10+1,1,1)) -> 0.89097222 | D10: =SUMIFS('Zápisník letů'!$L$2:$L$1018,'Zápisník letů'!$A$2:$A$1018,">="&DATE($A10,1,1),'Zápisník letů'!$A$2:$A$1018,"<"&DATE($A10+1,1,1),'Zápisník letů'!$Q$2:$Q$1018,"PIC") -> 0.31041667 | E10: =SUMIFS('Zápisník letů'!$L$2:$L$1018,'Zápisník letů'!$A$2:$A$1018,">="&DATE($A10,1,1),'Zápisník letů'!$A$2:$A$1018,"<"&DATE($A10+1,1,1),'Zápisník letů'!$Q$2:$Q$1018,"PIC",'Zápisník letů'!$B$2:$B$1018,"ULL") -> 0.24097222 | F10: =SUMIFS('Zápisník letů'!$L$2:$L$1018,'Zápisník letů'!$A$2:$A$1018,">="&DATE($A10,1,1),'Zápisník letů'!$A$2:$A$1018,"<"&DATE($A10+1,1,1),'Zápisník letů'!$Q$2:$Q$1018,"PIC",'Zápisník letů'!$B$2:$B$1018,"EASA") -> 0.069444444 | G10: =SUMIFS('Zápisník letů'!$L$2:$L$1018,'Zápisník letů'!$A$2:$A$1018,">="&DATE($A10,1,1),'Zápisník letů'!$A$2:$A$1018,"<"&DATE($A10+1,1,1),'Zápisník letů'!$Q$2:$Q$1018,"DUAL") -> 0 | H10: =SUMIFS('Zápisník letů'!$L$2:$L$1018,'Zápisník letů'!$A$2:$A$1018,">="&DATE($A10,1,1),'Zápisník letů'!$A$2:$A$1018,"<"&DATE($A10+1,1,1),'Zápisník letů'!$Q$2:$Q$1018,"INSTRUKTOR") -> 0 | I10: =SUMIFS('Zápisník letů'!$L$2:$L$1018,'Zápisník letů'!$A$2:$A$1018,">="&DATE($A10,1,1),'Zápisník letů'!$A$2:$A$1018,"<"&DATE($A10+1,1,1),'Zápisník letů'!$Q$2:$Q$1018,"SAFETY PILOT") -> 0.58055556 | J10: =SUMIFS('Zápisník letů'!$L$2:$L$1018,'Zápisník letů'!$A$2:$A$1018,">="&DATE($A10,1,1),'Zápisník letů'!$A$2:$A$1018,"<"&DATE($A10+1,1,1),'Zápisník letů'!$B$2:$B$1018,"ULL") -> 0.37152778 | K10: =SUMIFS('Zápisník letů'!$L$2:$L$1018,'Zápisník letů'!$A$2:$A$1018,">="&DATE($A10,1,1),'Zápisník letů'!$A$2:$A$1018,"<"&DATE($A10+1,1,1),'Zápisník letů'!$B$2:$B$1018,"EASA") -> 0.51944444 | L10: =SUMIFS('Zápisník letů'!$N$2:$N$1018,'Zápisník letů'!$A$2:$A$1018,">="&DATE($A10,1,1),'Zápisník letů'!$A$2:$A$1018,"<"&DATE($A10+1,1,1)) -> 23 | M10: =SUMIFS('Zápisník letů'!$T$2:$T$1018,'Zápisník letů'!$A$2:$A$1018,">="&DATE($A10,1,1),'Zápisník letů'!$A$2:$A$1018,"<"&DATE($A10+1,1,1)) -> 91691.84
A11: 2027 | B11: =COUNTIFS('Zápisník letů'!$A$2:$A$1018,">="&DATE($A11,1,1),'Zápisník letů'!$A$2:$A$1018,"<"&DATE($A11+1,1,1)) -> 0 | C11: =SUMIFS('Zápisník letů'!$L$2:$L$1018,'Zápisník letů'!$A$2:$A$1018,">="&DATE($A11,1,1),'Zápisník letů'!$A$2:$A$1018,"<"&DATE($A11+1,1,1)) -> 0 | D11: =SUMIFS('Zápisník letů'!$L$2:$L$1018,'Zápisník letů'!$A$2:$A$1018,">="&DATE($A11,1,1),'Zápisník letů'!$A$2:$A$1018,"<"&DATE($A11+1,1,1),'Zápisník letů'!$Q$2:$Q$1018,"PIC") -> 0 | E11: =SUMIFS('Zápisník letů'!$L$2:$L$1018,'Zápisník letů'!$A$2:$A$1018,">="&DATE($A11,1,1),'Zápisník letů'!$A$2:$A$1018,"<"&DATE($A11+1,1,1),'Zápisník letů'!$Q$2:$Q$1018,"PIC",'Zápisník letů'!$B$2:$B$1018,"ULL") -> 0 | F11: =SUMIFS('Zápisník letů'!$L$2:$L$1018,'Zápisník letů'!$A$2:$A$1018,">="&DATE($A11,1,1),'Zápisník letů'!$A$2:$A$1018,"<"&DATE($A11+1,1,1),'Zápisník letů'!$Q$2:$Q$1018,"PIC",'Zápisník letů'!$B$2:$B$1018,"EASA") -> 0 | G11: =SUMIFS('Zápisník letů'!$L$2:$L$1018,'Zápisník letů'!$A$2:$A$1018,">="&DATE($A11,1,1),'Zápisník letů'!$A$2:$A$1018,"<"&DATE($A11+1,1,1),'Zápisník letů'!$Q$2:$Q$1018,"DUAL") -> 0 | H11: =SUMIFS('Zápisník letů'!$L$2:$L$1018,'Zápisník letů'!$A$2:$A$1018,">="&DATE($A11,1,1),'Zápisník letů'!$A$2:$A$1018,"<"&DATE($A11+1,1,1),'Zápisník letů'!$Q$2:$Q$1018,"INSTRUKTOR") -> 0 | I11: =SUMIFS('Zápisník letů'!$L$2:$L$1018,'Zápisník letů'!$A$2:$A$1018,">="&DATE($A11,1,1),'Zápisník letů'!$A$2:$A$1018,"<"&DATE($A11+1,1,1),'Zápisník letů'!$Q$2:$Q$1018,"SAFETY PILOT") -> 0 | J11: =SUMIFS('Zápisník letů'!$L$2:$L$1018,'Zápisník letů'!$A$2:$A$1018,">="&DATE($A11,1,1),'Zápisník letů'!$A$2:$A$1018,"<"&DATE($A11+1,1,1),'Zápisník letů'!$B$2:$B$1018,"ULL") -> 0 | K11: =SUMIFS('Zápisník letů'!$L$2:$L$1018,'Zápisník letů'!$A$2:$A$1018,">="&DATE($A11,1,1),'Zápisník letů'!$A$2:$A$1018,"<"&DATE($A11+1,1,1),'Zápisník letů'!$B$2:$B$1018,"EASA") -> 0 | L11: =SUMIFS('Zápisník letů'!$N$2:$N$1018,'Zápisník letů'!$A$2:$A$1018,">="&DATE($A11,1,1),'Zápisník letů'!$A$2:$A$1018,"<"&DATE($A11+1,1,1)) -> 0 | M11: =SUMIFS('Zápisník letů'!$T$2:$T$1018,'Zápisník letů'!$A$2:$A$1018,">="&DATE($A11,1,1),'Zápisník letů'!$A$2:$A$1018,"<"&DATE($A11+1,1,1)) -> 0
A12: 2028 | B12: =COUNTIFS('Zápisník letů'!$A$2:$A$1018,">="&DATE($A12,1,1),'Zápisník letů'!$A$2:$A$1018,"<"&DATE($A12+1,1,1)) -> 0 | C12: =SUMIFS('Zápisník letů'!$L$2:$L$1018,'Zápisník letů'!$A$2:$A$1018,">="&DATE($A12,1,1),'Zápisník letů'!$A$2:$A$1018,"<"&DATE($A12+1,1,1)) -> 0 | D12: =SUMIFS('Zápisník letů'!$L$2:$L$1018,'Zápisník letů'!$A$2:$A$1018,">="&DATE($A12,1,1),'Zápisník letů'!$A$2:$A$1018,"<"&DATE($A12+1,1,1),'Zápisník letů'!$Q$2:$Q$1018,"PIC") -> 0 | E12: =SUMIFS('Zápisník letů'!$L$2:$L$1018,'Zápisník letů'!$A$2:$A$1018,">="&DATE($A12,1,1),'Zápisník letů'!$A$2:$A$1018,"<"&DATE($A12+1,1,1),'Zápisník letů'!$Q$2:$Q$1018,"PIC",'Zápisník letů'!$B$2:$B$1018,"ULL") -> 0 | F12: =SUMIFS('Zápisník letů'!$L$2:$L$1018,'Zápisník letů'!$A$2:$A$1018,">="&DATE($A12,1,1),'Zápisník letů'!$A$2:$A$1018,"<"&DATE($A12+1,1,1),'Zápisník letů'!$Q$2:$Q$1018,"PIC",'Zápisník letů'!$B$2:$B$1018,"EASA") -> 0 | G12: =SUMIFS('Zápisník letů'!$L$2:$L$1018,'Zápisník letů'!$A$2:$A$1018,">="&DATE($A12,1,1),'Zápisník letů'!$A$2:$A$1018,"<"&DATE($A12+1,1,1),'Zápisník letů'!$Q$2:$Q$1018,"DUAL") -> 0 | H12: =SUMIFS('Zápisník letů'!$L$2:$L$1018,'Zápisník letů'!$A$2:$A$1018,">="&DATE($A12,1,1),'Zápisník letů'!$A$2:$A$1018,"<"&DATE($A12+1,1,1),'Zápisník letů'!$Q$2:$Q$1018,"INSTRUKTOR") -> 0 | I12: =SUMIFS('Zápisník letů'!$L$2:$L$1018,'Zápisník letů'!$A$2:$A$1018,">="&DATE($A12,1,1),'Zápisník letů'!$A$2:$A$1018,"<"&DATE($A12+1,1,1),'Zápisník letů'!$Q$2:$Q$1018,"SAFETY PILOT") -> 0 | J12: =SUMIFS('Zápisník letů'!$L$2:$L$1018,'Zápisník letů'!$A$2:$A$1018,">="&DATE($A12,1,1),'Zápisník letů'!$A$2:$A$1018,"<"&DATE($A12+1,1,1),'Zápisník letů'!$B$2:$B$1018,"ULL") -> 0 | K12: =SUMIFS('Zápisník letů'!$L$2:$L$1018,'Zápisník letů'!$A$2:$A$1018,">="&DATE($A12,1,1),'Zápisník letů'!$A$2:$A$1018,"<"&DATE($A12+1,1,1),'Zápisník letů'!$B$2:$B$1018,"EASA") -> 0 | L12: =SUMIFS('Zápisník letů'!$N$2:$N$1018,'Zápisník letů'!$A$2:$A$1018,">="&DATE($A12,1,1),'Zápisník letů'!$A$2:$A$1018,"<"&DATE($A12+1,1,1)) -> 0 | M12: =SUMIFS('Zápisník letů'!$T$2:$T$1018,'Zápisník letů'!$A$2:$A$1018,">="&DATE($A12,1,1),'Zápisník letů'!$A$2:$A$1018,"<"&DATE($A12+1,1,1)) -> 0
A13: 2029 | B13: =COUNTIFS('Zápisník letů'!$A$2:$A$1018,">="&DATE($A13,1,1),'Zápisník letů'!$A$2:$A$1018,"<"&DATE($A13+1,1,1)) -> 0 | C13: =SUMIFS('Zápisník letů'!$L$2:$L$1018,'Zápisník letů'!$A$2:$A$1018,">="&DATE($A13,1,1),'Zápisník letů'!$A$2:$A$1018,"<"&DATE($A13+1,1,1)) -> 0 | D13: =SUMIFS('Zápisník letů'!$L$2:$L$1018,'Zápisník letů'!$A$2:$A$1018,">="&DATE($A13,1,1),'Zápisník letů'!$A$2:$A$1018,"<"&DATE($A13+1,1,1),'Zápisník letů'!$Q$2:$Q$1018,"PIC") -> 0 | E13: =SUMIFS('Zápisník letů'!$L$2:$L$1018,'Zápisník letů'!$A$2:$A$1018,">="&DATE($A13,1,1),'Zápisník letů'!$A$2:$A$1018,"<"&DATE($A13+1,1,1),'Zápisník letů'!$Q$2:$Q$1018,"PIC",'Zápisník letů'!$B$2:$B$1018,"ULL") -> 0 | F13: =SUMIFS('Zápisník letů'!$L$2:$L$1018,'Zápisník letů'!$A$2:$A$1018,">="&DATE($A13,1,1),'Zápisník letů'!$A$2:$A$1018,"<"&DATE($A13+1,1,1),'Zápisník letů'!$Q$2:$Q$1018,"PIC",'Zápisník letů'!$B$2:$B$1018,"EASA") -> 0 | G13: =SUMIFS('Zápisník letů'!$L$2:$L$1018,'Zápisník letů'!$A$2:$A$1018,">="&DATE($A13,1,1),'Zápisník letů'!$A$2:$A$1018,"<"&DATE($A13+1,1,1),'Zápisník letů'!$Q$2:$Q$1018,"DUAL") -> 0 | H13: =SUMIFS('Zápisník letů'!$L$2:$L$1018,'Zápisník letů'!$A$2:$A$1018,">="&DATE($A13,1,1),'Zápisník letů'!$A$2:$A$1018,"<"&DATE($A13+1,1,1),'Zápisník letů'!$Q$2:$Q$1018,"INSTRUKTOR") -> 0 | I13: =SUMIFS('Zápisník letů'!$L$2:$L$1018,'Zápisník letů'!$A$2:$A$1018,">="&DATE($A13,1,1),'Zápisník letů'!$A$2:$A$1018,"<"&DATE($A13+1,1,1),'Zápisník letů'!$Q$2:$Q$1018,"SAFETY PILOT") -> 0 | J13: =SUMIFS('Zápisník letů'!$L$2:$L$1018,'Zápisník letů'!$A$2:$A$1018,">="&DATE($A13,1,1),'Zápisník letů'!$A$2:$A$1018,"<"&DATE($A13+1,1,1),'Zápisník letů'!$B$2:$B$1018,"ULL") -> 0 | K13: =SUMIFS('Zápisník letů'!$L$2:$L$1018,'Zápisník letů'!$A$2:$A$1018,">="&DATE($A13,1,1),'Zápisník letů'!$A$2:$A$1018,"<"&DATE($A13+1,1,1),'Zápisník letů'!$B$2:$B$1018,"EASA") -> 0 | L13: =SUMIFS('Zápisník letů'!$N$2:$N$1018,'Zápisník letů'!$A$2:$A$1018,">="&DATE($A13,1,1),'Zápisník letů'!$A$2:$A$1018,"<"&DATE($A13+1,1,1)) -> 0 | M13: =SUMIFS('Zápisník letů'!$T$2:$T$1018,'Zápisník letů'!$A$2:$A$1018,">="&DATE($A13,1,1),'Zápisník letů'!$A$2:$A$1018,"<"&DATE($A13+1,1,1)) -> 0
A14: 2030 | B14: =COUNTIFS('Zápisník letů'!$A$2:$A$1018,">="&DATE($A14,1,1),'Zápisník letů'!$A$2:$A$1018,"<"&DATE($A14+1,1,1)) -> 0 | C14: =SUMIFS('Zápisník letů'!$L$2:$L$1018,'Zápisník letů'!$A$2:$A$1018,">="&DATE($A14,1,1),'Zápisník letů'!$A$2:$A$1018,"<"&DATE($A14+1,1,1)) -> 0 | D14: =SUMIFS('Zápisník letů'!$L$2:$L$1018,'Zápisník letů'!$A$2:$A$1018,">="&DATE($A14,1,1),'Zápisník letů'!$A$2:$A$1018,"<"&DATE($A14+1,1,1),'Zápisník letů'!$Q$2:$Q$1018,"PIC") -> 0 | E14: =SUMIFS('Zápisník letů'!$L$2:$L$1018,'Zápisník letů'!$A$2:$A$1018,">="&DATE($A14,1,1),'Zápisník letů'!$A$2:$A$1018,"<"&DATE($A14+1,1,1),'Zápisník letů'!$Q$2:$Q$1018,"PIC",'Zápisník letů'!$B$2:$B$1018,"ULL") -> 0 | F14: =SUMIFS('Zápisník letů'!$L$2:$L$1018,'Zápisník letů'!$A$2:$A$1018,">="&DATE($A14,1,1),'Zápisník letů'!$A$2:$A$1018,"<"&DATE($A14+1,1,1),'Zápisník letů'!$Q$2:$Q$1018,"PIC",'Zápisník letů'!$B$2:$B$1018,"EASA") -> 0 | G14: =SUMIFS('Zápisník letů'!$L$2:$L$1018,'Zápisník letů'!$A$2:$A$1018,">="&DATE($A14,1,1),'Zápisník letů'!$A$2:$A$1018,"<"&DATE($A14+1,1,1),'Zápisník letů'!$Q$2:$Q$1018,"DUAL") -> 0 | H14: =SUMIFS('Zápisník letů'!$L$2:$L$1018,'Zápisník letů'!$A$2:$A$1018,">="&DATE($A14,1,1),'Zápisník letů'!$A$2:$A$1018,"<"&DATE($A14+1,1,1),'Zápisník letů'!$Q$2:$Q$1018,"INSTRUKTOR") -> 0 | I14: =SUMIFS('Zápisník letů'!$L$2:$L$1018,'Zápisník letů'!$A$2:$A$1018,">="&DATE($A14,1,1),'Zápisník letů'!$A$2:$A$1018,"<"&DATE($A14+1,1,1),'Zápisník letů'!$Q$2:$Q$1018,"SAFETY PILOT") -> 0 | J14: =SUMIFS('Zápisník letů'!$L$2:$L$1018,'Zápisník letů'!$A$2:$A$1018,">="&DATE($A14,1,1),'Zápisník letů'!$A$2:$A$1018,"<"&DATE($A14+1,1,1),'Zápisník letů'!$B$2:$B$1018,"ULL") -> 0 | K14: =SUMIFS('Zápisník letů'!$L$2:$L$1018,'Zápisník letů'!$A$2:$A$1018,">="&DATE($A14,1,1),'Zápisník letů'!$A$2:$A$1018,"<"&DATE($A14+1,1,1),'Zápisník letů'!$B$2:$B$1018,"EASA") -> 0 | L14: =SUMIFS('Zápisník letů'!$N$2:$N$1018,'Zápisník letů'!$A$2:$A$1018,">="&DATE($A14,1,1),'Zápisník letů'!$A$2:$A$1018,"<"&DATE($A14+1,1,1)) -> 0 | M14: =SUMIFS('Zápisník letů'!$T$2:$T$1018,'Zápisník letů'!$A$2:$A$1018,">="&DATE($A14,1,1),'Zápisník letů'!$A$2:$A$1018,"<"&DATE($A14+1,1,1)) -> 0
A18: Funkce | B18: Letů | C18: Block time | D18: Náklady Kč | F18: Imatrikulace | G18: Typ | H18: Evidence | I18: Letů | J18: Celkem | K18: PIC | L18: Starty | M18: Náklady Kč
A19: PIC | B19: =COUNTIF('Zápisník letů'!$Q$2:$Q$1018,$A19) -> 146 | C19: =SUMIFS('Zápisník letů'!$L$2:$L$1018,'Zápisník letů'!$Q$2:$Q$1018,$A19) -> 8.8541667 | D19: =SUMIFS('Zápisník letů'!$T$2:$T$1018,'Zápisník letů'!$Q$2:$Q$1018,$A19) -> 467828.49 | F19: OK-BIC | G19: =IFERROR(INDEX('Zápisník letů'!$D$2:$D$1018,MATCH($F19,'Zápisník letů'!$C$2:$C$1018,0)),"") -> P208 | H19: =IFERROR(INDEX('Zápisník letů'!$B$2:$B$1018,MATCH($F19,'Zápisník letů'!$C$2:$C$1018,0)),"") -> EASA | I19: =COUNTIF('Zápisník letů'!$C$2:$C$1018,$F19) -> 12 | J19: =SUMIFS('Zápisník letů'!$L$2:$L$1018,'Zápisník letů'!$C$2:$C$1018,$F19) -> 0.50625 | K19: =SUMIFS('Zápisník letů'!$L$2:$L$1018,'Zápisník letů'!$C$2:$C$1018,$F19,'Zápisník letů'!$Q$2:$Q$1018,"PIC") -> 0.11458333 | L19: =SUMIFS('Zápisník letů'!$N$2:$N$1018,'Zápisník letů'!$C$2:$C$1018,$F19) -> 34 | M19: =SUMIFS('Zápisník letů'!$T$2:$T$1018,'Zápisník letů'!$C$2:$C$1018,$F19) -> 37179
A20: DUAL | B20: =COUNTIF('Zápisník letů'!$Q$2:$Q$1018,$A20) -> 33 | C20: =SUMIFS('Zápisník letů'!$L$2:$L$1018,'Zápisník letů'!$Q$2:$Q$1018,$A20) -> 1.3375 | D20: =SUMIFS('Zápisník letů'!$T$2:$T$1018,'Zápisník letů'!$Q$2:$Q$1018,$A20) -> 88069.33 | F20: OK-BID | G20: =IFERROR(INDEX('Zápisník letů'!$D$2:$D$1018,MATCH($F20,'Zápisník letů'!$C$2:$C$1018,0)),"") -> B23 | H20: =IFERROR(INDEX('Zápisník letů'!$B$2:$B$1018,MATCH($F20,'Zápisník letů'!$C$2:$C$1018,0)),"") -> EASA | I20: =COUNTIF('Zápisník letů'!$C$2:$C$1018,$F20) -> 2 | J20: =SUMIFS('Zápisník letů'!$L$2:$L$1018,'Zápisník letů'!$C$2:$C$1018,$F20) -> 0.072916667 | K20: =SUMIFS('Zápisník letů'!$L$2:$L$1018,'Zápisník letů'!$C$2:$C$1018,$F20,'Zápisník letů'!$Q$2:$Q$1018,"PIC") -> 0.020833333 | L20: =SUMIFS('Zápisník letů'!$N$2:$N$1018,'Zápisník letů'!$C$2:$C$1018,$F20) -> 9 | M20: =SUMIFS('Zápisník letů'!$T$2:$T$1018,'Zápisník letů'!$C$2:$C$1018,$F20) -> 5355
